Workbook

Sheet Hoja1
A1: Table 23 Average One-Year Transition Rates For Global Corporates By Rating Modifier (1981-2021)
A2: From/to | B2: AAA | C2: AA+ | D2: AA | E2: AA- | F2: A+ | G2: A | H2: A- | I2: BBB+ | J2: BBB | K2: BBB- | L2: BB+ | M2: BB | N2: BB- | O2: B+ | P2: B | Q2: B- | R2: CCC | S2: D | T2: NR
A3: AAA | B3: 0.8709 | C3: 0.0586 | D3: 0.025 | E3: 0.0068 | F3: 0.0016 | G3: 0.0024 | H3: 0.0013 | I3: 0 | J3: 0.0005 | K3: 0 | L3: 0.0003 | M3: 0.0005 | N3: 0.0003 | O3: 0 | P3: 0.0003 | Q3: 0 | R3: 0.0005 | S3: 0 | T3: 0.031
A4: AA+ | B4: 0.0221 | C4: 0.7968 | D4: 0.1059 | E4: 0.0338 | F4: 0.0068 | G4: 0.0032 | H4: 0.0018 | I4: 0.0005 | J4: 0.0009 | K4: 0.0005 | L4: 0 | M4: 0 | N4: 0 | O4: 0 | P4: 0 | Q4: 0 | R4: 0 | S4: 0 | T4: 0.0279
A5: AA | B5: 0.0041 | C5: 0.0131 | D5: 0.8099 | E5: 0.0842 | F5: 0.0263 | G5: 0.0112 | H5: 0.0035 | I5: 0.0038 | J5: 0.0013 | K5: 0.0008 | L5: 0.0005 | M5: 0.0003 | N5: 0.0002 | O5: 0.0002 | P5: 0 | Q5: 0.0002 | R5: 0.0005 | S5: 0.0002 | T5: 0.0399
A6: AA- | B6: 0.0004 | C6: 0.001 | D6: 0.0368 | E6: 0.7899 | F6: 0.0974 | G6: 0.0218 | H6: 0.0057 | I6: 0.0024 | J6: 0.0014 | K6: 0.0006 | L6: 0.0003 | M6: 0 | N6: 0 | O6: 0.0003 | P6: 0.0008 | Q6: 0 | R6: 0 | S6: 0.0003 | T6: 0.0409
A7: A+ | B7: 0 | C7: 0.0005 | D7: 0.0041 | E7: 0.0423 | F7: 0.7916 | G7: 0.0854 | H7: 0.0204 | I7: 0.0058 | J7: 0.0032 | K7: 0.0008 | L7: 0.0005 | M7: 0.0008 | N7: 0.0001 | O7: 0.0006 | P7: 0.0003 | Q7: 0 | R7: 0 | S7: 0.0005 | T7: 0.0431
A8: A | B8: 0.0003 | C8: 0.0004 | D8: 0.0021 | E8: 0.0039 | F8: 0.0519 | G8: 0.7936 | H8: 0.0661 | I8: 0.0232 | J8: 0.0081 | K8: 0.0025 | L8: 0.0009 | M8: 0.001 | N8: 0.0006 | O8: 0.0008 | P8: 0.0002 | Q8: 0 | R8: 0.0001 | S8: 0.0005 | T8: 0.044
A9: A- | B9: 0.0003 | C9: 0.0001 | D9: 0.0005 | E9: 0.0014 | F9: 0.0038 | G9: 0.0614 | H9: 0.7887 | I9: 0.0727 | J9: 0.0185 | K9: 0.0053 | L9: 0.0012 | M9: 0.0012 | N9: 0.001 | O9: 0.001 | P9: 0.0003 | Q9: 0.0001 | R9: 0.0003 | S9: 0.0005 | T9: 0.0416
A10: BBB+ | B10: 0 | C10: 0.0001 | D10: 0.0005 | E10: 0.0006 | F10: 0.0019 | G10: 0.0069 | H10: 0.0677 | I10: 0.7665 | J10: 0.0798 | K10: 0.015 | L10: 0.0034 | M10: 0.0026 | N10: 0.0012 | O10: 0.0014 | P10: 0.0009 | Q10: 0.0002 | R10: 0.0006 | S10: 0.0009 | T10: 0.0498
A11: BBB | B11: 0.0001 | C11: 0.0001 | D11: 0.0004 | E11: 0.0002 | F11: 0.0009 | G11: 0.0028 | H11: 0.0095 | I11: 0.0726 | J11: 0.7668 | K11: 0.062 | L11: 0.0128 | M11: 0.0063 | N11: 0.0026 | O11: 0.002 | P11: 0.001 | Q11: 0.0003 | R11: 0.0005 | S11: 0.0014 | T11: 0.0577
A12: BBB- | B12: 0.0001 | C12: 0.0001 | D12: 0.0002 | E12: 0.0004 | F12: 0.0006 | G12: 0.0013 | H12: 0.0023 | I12: 0.0108 | J12: 0.0903 | K12: 0.7287 | L12: 0.0557 | M12: 0.0201 | N12: 0.0081 | O12: 0.0036 | P12: 0.0021 | Q12: 0.0015 | R12: 0.0019 | S12: 0.0023 | T12: 0.0699
A13: BB+ | B13: 0.0004 | C13: 0 | D13: 0 | E13: 0.0003 | F13: 0.0003 | G13: 0.0008 | H13: 0.0008 | I13: 0.0037 | J13: 0.0149 | K13: 0.1078 | L13: 0.661 | M13: 0.077 | N13: 0.0257 | O13: 0.0097 | P13: 0.0051 | Q13: 0.0022 | R13: 0.0033 | S13: 0.0031 | T13: 0.0841
A14: BB | B14: 0 | C14: 0 | D14: 0.0003 | E14: 0.0001 | F14: 0 | G14: 0.0005 | H14: 0.0004 | I14: 0.0015 | J14: 0.0056 | K14: 0.0187 | L14: 0.095 | M14: 0.6534 | N14: 0.0865 | O14: 0.0236 | P14: 0.0103 | Q14: 0.0035 | R14: 0.0048 | S14: 0.0046 | T14: 0.091
... A19: CCC/C | B19: 0 | C19: 0 | D19: 0 | E19: 0 | F19: 0.0002 | G19: 0 | H19: 0.0007 | I19: 0.0004 | J19: 0.0007 | K19: 0.0004 | L19: 0.0002 | M19: 0.0013 | N19: 0.0034 | O19: 0.0085 | P19: 0.0253 | Q19: 0.1004 | R19: 0.4391 | S19: 0.2655 | T19: 0.1539

Sheet Ejemplo Indp Nvidia Henkel
A2: Nvidia | B2: AA-
A3: Henkel | B3: A
A5: From/to | B5: AAA | C5: AA+ | D5: AA | E5: AA- | F5: A+ | G5: A | H5: A- | I5: BBB+ | J5: BBB | K5: BBB- | L5: BB+ | M5: BB | N5: BB- | O5: B+ | P5: B | Q5: B- | R5: CCC | S5: D | T5: NR
A6: AAA | B6: =Hoja1!B3 -> 0.8709 | C6: =Hoja1!C3 -> 0.0586 | D6: =Hoja1!D3 -> 0.025 | E6: =Hoja1!E3 -> 0.0068 | F6: =Hoja1!F3 -> 0.0016 | G6: =Hoja1!G3 -> 0.0024 | H6: =Hoja1!H3 -> 0.0013 | I6: =Hoja1!I3 -> 0 | ... T6: =Hoja1!T3 -> 0.031
A7: AA+ | B7: =Hoja1!B4 -> 0.0221 | C7: =Hoja1!C4 -> 0.7968 | D7: =Hoja1!D4 -> 0.1059 | E7: =Hoja1!E4 -> 0.0338 | F7: =Hoja1!F4 -> 0.0068 | G7: =Hoja1!G4 -> 0.0032 | H7: =Hoja1!H4 -> 0.0018 | I7: =Hoja1!I4 -> 0.0005 | ... T7: =Hoja1!T4 -> 0.0279
A8: AA | B8: =Hoja1!B5 -> 0.0041 | C8: =Hoja1!C5 -> 0.0131 | D8: =Hoja1!D5 -> 0.8099 | E8: =Hoja1!E5 -> 0.0842 | F8: =Hoja1!F5 -> 0.0263 | G8: =Hoja1!G5 -> 0.0112 | H8: =Hoja1!H5 -> 0.0035 | I8: =Hoja1!I5 -> 0.0038 | ... T8: =Hoja1!T5 -> 0.0399
A9: AA- | B9: =Hoja1!B6 -> 0.0004 | C9: =Hoja1!C6 -> 0.001 | D9: =Hoja1!D6 -> 0.0368 | E9: =Hoja1!E6 -> 0.7899 | F9: =Hoja1!F6 -> 0.0974 | G9: =Hoja1!G6 -> 0.0218 | H9: =Hoja1!H6 -> 0.0057 | I9: =Hoja1!I6 -> 0.0024 | ... T9: =Hoja1!T6 -> 0.0409
A10: A+ | B10: =Hoja1!B7 -> 0 | C10: =Hoja1!C7 -> 0.0005 | D10: =Hoja1!D7 -> 0.0041 | E10: =Hoja1!E7 -> 0.0423 | F10: =Hoja1!F7 -> 0.7916 | G10: =Hoja1!G7 -> 0.0854 | H10: =Hoja1!H7 -> 0.0204 | I10: =Hoja1!I7 -> 0.0058 | ... T10: =Hoja1!T7 -> 0.0431
A11: A | B11: =Hoja1!B8 -> 0.0003 | C11: =Hoja1!C8 -> 0.0004 | D11: =Hoja1!D8 -> 0.0021 | E11: =Hoja1!E8 -> 0.0039 | F11: =Hoja1!F8 -> 0.0519 | G11: =Hoja1!G8 -> 0.7936 | H11: =Hoja1!H8 -> 0.0661 | I11: =Hoja1!I8 -> 0.0232 | ... T11: =Hoja1!T8 -> 0.044
A12: A- | B12: =Hoja1!B9 -> 0.0003 | C12: =Hoja1!C9 -> 0.0001 | D12: =Hoja1!D9 -> 0.0005 | E12: =Hoja1!E9 -> 0.0014 | F12: =Hoja1!F9 -> 0.0038 | G12: =Hoja1!G9 -> 0.0614 | H12: =Hoja1!H9 -> 0.7887 | I12: =Hoja1!I9 -> 0.0727 | ... T12: =Hoja1!T9 -> 0.0416 | V12: wnj ewjne
A13: BBB+ | B13: =Hoja1!B10 -> 0 | C13: =Hoja1!C10 -> 0.0001 | D13: =Hoja1!D10 -> 0.0005 | E13: =Hoja1!E10 -> 0.0006 | F13: =Hoja1!F10 -> 0.0019 | G13: =Hoja1!G10 -> 0.0069 | H13: =Hoja1!H10 -> 0.0677 | I13: =Hoja1!I10 -> 0.7665 | ... T13: =Hoja1!T10 -> 0.0498
A14: BBB | B14: =Hoja1!B11 -> 0.0001 | C14: =Hoja1!C11 -> 0.0001 | D14: =Hoja1!D11 -> 0.0004 | E14: =Hoja1!E11 -> 0.0002 | F14: =Hoja1!F11 -> 0.0009 | G14: =Hoja1!G11 -> 0.0028 | H14: =Hoja1!H11 -> 0.0095 | I14: =Hoja1!I11 -> 0.0726 | ... T14: =Hoja1!T11 -> 0.0577
A15: BBB- | B15: =Hoja1!B12 -> 0.0001 | C15: =Hoja1!C12 -> 0.0001 | D15: =Hoja1!D12 -> 0.0002 | E15: =Hoja1!E12 -> 0.0004 | F15: =Hoja1!F12 -> 0.0006 | G15: =Hoja1!G12 -> 0.0013 | H15: =Hoja1!H12 -> 0.0023 | I15: =Hoja1!I12 -> 0.0108 | ... T15: =Hoja1!T12 -> 0.0699
A16: BB+ | B16: =Hoja1!B13 -> 0.0004 | C16: =Hoja1!C13 -> 0 | D16: =Hoja1!D13 -> 0 | E16: =Hoja1!E13 -> 0.0003 | F16: =Hoja1!F13 -> 0.0003 | G16: =Hoja1!G13 -> 0.0008 | H16: =Hoja1!H13 -> 0.0008 | I16: =Hoja1!I13 -> 0.0037 | ... T16: =Hoja1!T13 -> 0.0841
A17: BB | B17: =Hoja1!B14 -> 0 | C17: =Hoja1!C14 -> 0 | D17: =Hoja1!D14 -> 0.0003 | E17: =Hoja1!E14 -> 0.0001 | F17: =Hoja1!F14 -> 0 | G17: =Hoja1!G14 -> 0.0005 | H17: =Hoja1!H14 -> 0.0004 | I17: =Hoja1!I14 -> 0.0015 | ... T17: =Hoja1!T14 -> 0.091
A18: BB- | B18: =Hoja1!B15 -> 0 | C18: =Hoja1!C15 -> 0 | D18: =Hoja1!D15 -> 0 | E18: =Hoja1!E15 -> 0.0001 | F18: =Hoja1!F15 -> 0.0001 | G18: =Hoja1!G15 -> 0.0001 | H18: =Hoja1!H15 -> 0.0004 | I18: =Hoja1!I15 -> 0.0009 | ... T18: =Hoja1!T15 -> 0.1037
A19: B+ | B19: =Hoja1!B16 -> 0 | C19: =Hoja1!C16 -> 0.0001 | D19: =Hoja1!D16 -> 0 | E19: =Hoja1!E16 -> 0.0003 | F19: =Hoja1!F16 -> 0 | G19: =Hoja1!G16 -> 0.0003 | H19: =Hoja1!H16 -> 0.0006 | I19: =Hoja1!I16 -> 0.0004 | ... T19: =Hoja1!T16 -> 0.1147
A20: B | B20: =Hoja1!B17 -> 0 | C20: =Hoja1!C17 -> 0 | D20: =Hoja1!D17 -> 0.0001 | E20: =Hoja1!E17 -> 0.0001 | F20: =Hoja1!F17 -> 0 | G20: =Hoja1!G17 -> 0.0003 | H20: =Hoja1!H17 -> 0.0003 | I20: =Hoja1!I17 -> 0.0001 | ... T20: =Hoja1!T17 -> 0.1266
A21: B- | B21: =Hoja1!B18 -> 0 | C21: =Hoja1!C18 -> 0 | D21: =Hoja1!D18 -> 0 | E21: =Hoja1!E18 -> 0 | F21: =Hoja1!F18 -> 0.0001 | G21: =Hoja1!G18 -> 0.0003 | H21: =Hoja1!H18 -> 0 | I21: =Hoja1!I18 -> 0.0005 | ... T21: =Hoja1!T18 -> 0.1417
A22: CCC/C | B22: =Hoja1!B19 -> 0 | C22: =Hoja1!C19 -> 0 | D22: =Hoja1!D19 -> 0 | E22: =Hoja1!E19 -> 0 | F22: =Hoja1!F19 -> 0.0002 | G22: =Hoja1!G19 -> 0 | H22: =Hoja1!H19 -> 0.0007 | I22: =Hoja1!I19 -> 0.0004 | ... T22: =Hoja1!T19 -> 0.1539
C25: 1 | D25: 2 | E25: 3 | F25: 4 | G25: 5 | S25: For large manufacturing firms
A26: Treasury Yield Curve | C26: 0.0369 | D26: 0.0379 | E26: 0.0378 | F26: =(E26+G26)/2 -> 0.0385 | G26: 0.0392 | S26: If interest coverage ratio is
A28: Credit Rating | C28: 1 | D28: 2 | E28: 3 | F28: 4 | G28: 5 | S28: > | T28: ≤ to | U28: Rating is | V28: Spread is
A29: AAA | C29: =C26+$V$29 -> 0.0438 | D29: =D26+$V$29 -> 0.0448 | E29: =E26+$V$29 -> 0.0447 | F29: =F26+$V$29 -> 0.0454 | G29: =G26+$V$29 -> 0.0461 | S29: 12.5 | T29: 100000 | U29: Aaa/AAA | V29: 0.0069
A30: AA+ | C30: =(C29+C31)/2 -> 0.0446 | D30: =(D29+D31)/2 -> 0.0456 | E30: =(E29+E31)/2 -> 0.0455 | F30: =(F29+F31)/2 -> 0.0462 | G30: =(G29+G31)/2 -> 0.0469 | S30: 9.5 | T30: 12.499999 | U30: Aa2/AA | V30: 0.0085
A31: AA | C31: =C26+$V$30 -> 0.0454 | D31: =D26+$V$30 -> 0.0464 | E31: =E26+$V$30 -> 0.0463 | F31: =F26+$V$30 -> 0.047 | G31: =G26+$V$30 -> 0.0477 | S31: 7.5 | T31: 9.499999 | U31: A1/A+ | V31: 0.0107
A32: AA- | C32: =(C31+C33)/2 -> 0.0465 | D32: =(D31+D33)/2 -> 0.0475 | E32: =(E31+E33)/2 -> 0.0474 | F32: =(F31+F33)/2 -> 0.0481 | G32: =(G31+G33)/2 -> 0.0488 | S32: 6 | T32: 7.499999 | U32: A2/A | V32: 0.0118
A33: A+ | C33: =C26+$V$31 -> 0.0476 | D33: =D26+$V$31 -> 0.0486 | E33: =E26+$V$31 -> 0.0485 | F33: =F26+$V$31 -> 0.0492 | G33: =G26+$V$31 -> 0.0499 | S33: 4.5 | T33: 5.999999 | U33: A3/A- | V33: 0.0133
A34: A | C34: =C26+$V$32 -> 0.0487 | D34: =D26+$V$32 -> 0.0497 | E34: =E26+$V$32 -> 0.0496 | F34: =F26+$V$32 -> 0.0503 | G34: =G26+$V$32 -> 0.051 | S34: 4 | T34: 4.499999 | U34: Baa2/BBB | V34: 0.0171
A35: A- | C35: =C26+$V$33 -> 0.0502 | D35: =D26+$V$33 -> 0.0512 | E35: =E26+$V$33 -> 0.0511 | F35: =F26+$V$33 -> 0.0518 | G35: =G26+$V$33 -> 0.0525 | S35: 3.5 | T35: 3.9999999 | U35: Ba1/BB+ | V35: 0.0231
A36: BBB+ | C36: =(C35+C37)/2 -> 0.0521 | D36: =(D35+D37)/2 -> 0.0531 | E36: =(E35+E37)/2 -> 0.053 | F36: =(F35+F37)/2 -> 0.0537 | G36: =(G35+G37)/2 -> 0.0544 | S36: 3 | T36: 3.499999 | U36: Ba2/BB | V36: 0.0277
A37: BBB | C37: =C26+$V$34 -> 0.054 | D37: =D26+$V$34 -> 0.055 | E37: =E26+$V$34 -> 0.0549 | F37: =F26+$V$34 -> 0.0556 | G37: =G26+$V$34 -> 0.0563 | S37: 2.5 | T37: 2.999999 | U37: B1/B+ | V37: 0.0405
A38: BBB- | C38: =(C37+C39)/2 -> 0.057 | D38: =(D37+D39)/2 -> 0.058 | E38: =(E37+E39)/2 -> 0.0579 | F38: =(F37+F39)/2 -> 0.0586 | G38: =(G37+G39)/2 -> 0.0593 | S38: 2 | T38: 2.499999 | U38: B2/B | V38: 0.0486
A39: BB+ | C39: =C26+$V$35 -> 0.06 | D39: =D26+$V$35 -> 0.061 | E39: =E26+$V$35 -> 0.0609 | F39: =F26+$V$35 -> 0.0616 | G39: =G26+$V$35 -> 0.0623 | S39: 1.5 | T39: 1.999999 | U39: B3/B- | V39: 0.0594
A40: BB | C40: =C26+$V$36 -> 0.0646 | D40: =D26+$V$36 -> 0.0656 | E40: =E26+$V$36 -> 0.0655 | F40: =F26+$V$36 -> 0.0662 | G40: =G26+$V$36 -> 0.0669 | S40: 1.25 | T40: 1.499999 | U40: Caa/CCC | V40: 0.0946
A41: BB- | C41: =(C40+C42)/2 -> 0.071 | D41: =(D40+D42)/2 -> 0.072 | E41: =(E40+E42)/2 -> 0.0719 | F41: =(F40+F42)/2 -> 0.0726 | G41: =(G40+G42)/2 -> 0.0733 | S41: 0.8 | T41: 1.249999 | U41: Ca2/CC | V41: 0.0997
A42: B+ | C42: =C26+$V$37 -> 0.0774 | D42: =D26+$V$37 -> 0.0784 | E42: =E26+$V$37 -> 0.0783 | F42: =F26+$V$37 -> 0.079 | G42: =G26+$V$37 -> 0.0797 | S42: 0.5 | T42: 0.799999 | U42: C2/C | V42: 0.1309
A43: B | C43: =C26+$V$38 -> 0.0855 | D43: =D26+$V$38 -> 0.0865 | E43: =E26+$V$38 -> 0.0864 | F43: =F26+$V$38 -> 0.0871 | G43: =G26+$V$38 -> 0.0878 | S43: -100000 | T43: 0.499999 | U43: D2/D | V43: 0.1744
A44: B- | C44: =C26+$V$39 -> 0.0963 | D44: =D26+$V$39 -> 0.0973 | E44: =E26+$V$39 -> 0.0972 | F44: =F26+$V$39 -> 0.0979 | G44: =G26+$V$39 -> 0.0986
A45: CCC/C | C45: =C26+$V$40 -> 0.1315 | D45: =D26+$V$40 -> 0.1325 | E45: =E26+$V$40 -> 0.1324 | F45: =F26+$V$40 -> 0.1331 | G45: =G26+$V$40 -> 0.1338
...

Sheet CreditMetrics Correlacionado
A2: ='Ejemplo Indp Nvidia Henkel'!A2 -> Nvidia | B2: ='Ejemplo Indp Nvidia Henkel'!B2 -> AA-
A3: ='Ejemplo Indp Nvidia Henkel'!A3 -> Henkel | B3: ='Ejemplo Indp Nvidia Henkel'!B3 -> A
A5: From/to | B5: AAA | C5: AA+ | D5: AA | E5: AA- | F5: A+ | G5: A | H5: A- | I5: BBB+ | J5: BBB | K5: BBB- | L5: BB+ | M5: BB | N5: BB- | O5: B+ | P5: B | Q5: B- | R5: CCC | S5: D | T5: NR
A6: AA- | B6: =Hoja1!B5 -> 0.0041 | C6: =Hoja1!C5 -> 0.0131 | D6: =Hoja1!D5 -> 0.8099 | E6: =Hoja1!E5 -> 0.0842 | F6: =Hoja1!F5 -> 0.0263 | G6: =Hoja1!G5 -> 0.0112 | H6: =Hoja1!H5 -> 0.0035 | I6: =Hoja1!I5 -> 0.0038 | ... T6: =Hoja1!T5 -> 0.0399 | U6: =SMALL(B6:T6,6) -> 0.0003
A7: Prob Acumulada | B7: =SUM($B6:B6) -> 0.0041 | C7: =SUM($B6:C6) -> 0.0172 | D7: =SUM($B6:D6) -> 0.8271 | E7: =SUM($B6:E6) -> 0.9113 | F7: =SUM($B6:F6) -> 0.9376 | G7: =SUM($B6:G6) -> 0.9488 | H7: =SUM($B6:H6) -> 0.9523 | I7: =SUM($B6:I6) -> 0.9561 | ... T7: =SUM($B6:T6) -> 1.0002
A8: N-1() | B8: =_xlfn.NORM.INV(B7,0,1) -> -2.6437219 | C8: =_xlfn.NORM.INV(C7,0,1) -> -2.1153515 | D8: =_xlfn.NORM.INV(D7,0,1) -> 0.94276718 | E8: =_xlfn.NORM.INV(E7,0,1) -> 1.3488038 | F8: =_xlfn.NORM.INV(F7,0,1) -> 1.5349342 | G8: =_xlfn.NORM.INV(G7,0,1) -> 1.6333281 | H8: =_xlfn.NORM.INV(H7,0,1) -> 1.6675756 | I8: =_xlfn.NORM.INV(I7,0,1) -> 1.7071187 | ... T8: =_xlfn.NORM.INV(T7,0,1) -> #NUM!
A10: A | B10: =Hoja1!B8 -> 0.0003 | C10: =Hoja1!C8 -> 0.0004 | D10: =Hoja1!D8 -> 0.0021 | E10: =Hoja1!E8 -> 0.0039 | F10: =Hoja1!F8 -> 0.0519 | G10: =Hoja1!G8 -> 0.7936 | H10: =Hoja1!H8 -> 0.0661 | I10: =Hoja1!I8 -> 0.0232 | ... T10: =Hoja1!T8 -> 0.044 | U10: =SMALL(B10:T10,4) -> 0.0003
A11: Prob Acumulada | B11: =U10 -> 0.0003 | C11: =SUM($B10:C10) -> 0.0007 | D11: =SUM($B10:D10) -> 0.0028 | E11: =SUM($B10:E10) -> 0.0067 | F11: =SUM($B10:F10) -> 0.0586 | G11: =SUM($B10:G10) -> 0.8522 | H11: =SUM($B10:H10) -> 0.9183 | I11: =SUM($B10:I10) -> 0.9415 | J11: =SUM($B10:J10) -> 0.9496 | ... T11: =SUM($B10:T10) -> 1.0002
A12: N-1() | B12: =_xlfn.NORM.INV(B11,0,1) -> -3.4316144 | C12: =_xlfn.NORM.INV(C11,0,1) -> -3.1946511 | D12: =_xlfn.NORM.INV(D11,0,1) -> -2.7703272 | E12: =_xlfn.NORM.INV(E11,0,1) -> -2.4729577 | F12: =_xlfn.NORM.INV(F11,0,1) -> -1.5666351 | G12: =_xlfn.NORM.INV(G11,0,1) -> 1.0459156 | H12: =_xlfn.NORM.INV(H11,0,1) -> 1.3937272 | I12: =_xlfn.NORM.INV(I11,0,1) -> 1.5674909 | ... T12: =_xlfn.NORM.INV(T11,0,1) -> #NUM!
A14: xNvidia = | B14: =B17*B16+B18*_xlfn.NORM.S.INV(RAND()) -> -0.2798297 | C14: =_xlfn.FORMULATEXT(B14) -> =B17*B16+B18*NORM.S.INV(RAND())
A15: xHenhel = | B15: =B17*B16+B18*_xlfn.NORM.S.INV(RAND()) -> -0.047268519 | C15: =_xlfn.FORMULATEXT(B15) -> =B17*B16+B18*NORM.S.INV(RAND())
A16: F = | B16: =_xlfn.NORM.INV(RAND(),0,1) -> -0.78610179
A17: ai = | B17: =CORREL('Henkel ST Stock Price History ('!G75:G574,NVIDIA!G65:G564) -> 0.022918693 | C17: La proxy de ai es la correlación de los rendimientos de las acciones de las dos empresas
A18: raiz(1-ai2) = | B18: =SQRT(1-(B17^2)) -> 0.99973733
A19: r = | B19: =B17^2 -> 0.00052526647 | C19: 1-r = | D19: =1-B19 -> 0.99947473
A22: INvidia = | B22: =IF($B$14<B8,1,0) -> 0 | C22: =IF(AND($B$14<C8,$B$14>B8),1,0) -> 0 | D22: =IF(AND($B$14<D8,$B$14>C8),1,0) -> 1 | E22: =IF(AND($B$14<E8,$B$14>D8),1,0) -> 0 | F22: =IF(AND($B$14<F8,$B$14>E8),1,0) -> 0 | G22: =IF(AND($B$14<G8,$B$14>F8),1,0) -> 0 | H22: =IF(AND($B$14<H8,$B$14>G8),1,0) -> 0 | I22: =IF(AND($B$14<I8,$B$14>H8),1,0) -> 0 | J22: =IF(AND($B$14<J8,$B$14>I8),1,0) -> 0 | ... S22: =IF(AND($B$14<S8,$B$14>R8),1,0) -> 0
B23: {=TRANSPOSE('Ejemplo Indp Nvidia Henkel'!U53:U70)} -> 101.75754 | C23: 101.40426 | D23: 101.05255 | E23: 100.57149 | F23: 100.09334 | G23: 99.618092 | H23: 98.974662 | I23: 98.167252 | J23: 97.368241 | K23: 96.123494 | L23: 94.899028 | M23: 93.060012 | N23: 90.576612 | O23: 88.177552 | P23: 85.256904 | Q23: 81.553281 | R23: 70.834964 | S23: 44.17
B24: =B23*B22 -> 0 | C24: =C23*C22 -> 0 | D24: =D23*D22 -> 101.05255 | E24: =E23*E22 -> 0 | F24: =F23*F22 -> 0 | G24: =G23*G22 -> 0 | H24: =H23*H22 -> 0 | I24: =I23*I22 -> 0 | ... S24: =S23*S22 -> 0
A27: IHenkel = | B27: =IF($B$15<B12,1,0) -> 0 | C27: =IF(AND($B$15<C12,$B$15>B12),1,0) -> 0 | D27: =IF(AND($B$15<D12,$B$15>C12),1,0) -> 0 | E27: =IF(AND($B$15<E12,$B$15>D12),1,0) -> 0 | F27: =IF(AND($B$15<F12,$B$15>E12),1,0) -> 0 | G27: =IF(AND($B$15<G12,$B$15>F12),1,0) -> 1 | H27: =IF(AND($B$15<H12,$B$15>G12),1,0) -> 0 | I27: =IF(AND($B$15<I12,$B$15>H12),1,0) -> 0 | J27: =IF(AND($B$15<J12,$B$15>I12),1,0) -> 0 | ... S27: =IF(AND($B$15<S12,$B$15>R12),1,0) -> 0
B28: {=TRANSPOSE('Ejemplo Indp Nvidia Henkel'!H53:H70)} -> 101.75754 | C28: 101.40426 | D28: 101.05255 | E28: 100.57149 | F28: 100.09334 | G28: 99.618092 | H28: 98.974662 | I28: 98.167252 | J28: 97.368241 | K28: 96.123494 | L28: 94.899028 | M28: 93.060012 | N28: 90.576612 | O28: 88.177552 | P28: 85.256904 | Q28: 81.553281 | R28: 70.834964 | S28: 43.18
B29: =B28*B27 -> 0 | C29: =C28*C27 -> 0 | D29: =D28*D27 -> 0 | E29: =E28*E27 -> 0 | F29: =F28*F27 -> 0 | G29: =G28*G27 -> 99.618092 | H29: =H28*H27 -> 0 | I29: =I28*I27 -> 0 | ... S29: =S28*S27 -> 0
A35: Portafolio = | B35: =SUM(B29:S29)+SUM(B24:S24) -> 200.67064

Sheet NVIDIA
A1: Date | B1: Price | C1: Open | D1: High | E1: Low | F1: Vol.
A2: 44986 | B2: 14.31 | C2: 14.85 | D2: 15 | E2: 14.1 | F2: 401.28M
A3: 45017 | B3: 14.75 | C3: 14.57 | D3: 14.85 | E3: 14.24 | F3: 431.32M | G3: =B3/B2-1 -> 0.030747729
A4: 45047 | B4: 14.27 | C4: 14.49 | D4: 14.56 | E4: 14.15 | F4: 389.17M | G4: =B4/B3-1 -> -0.032542373
A5: 45078 | B5: 14.86 | C5: 14.47 | D5: 15.01 | E5: 14.03 | F5: 405.04M | G5: =B5/B4-1 -> 0.04134548
A6: 45170 | B6: 15.63 | C6: 15.28 | D6: 16.06 | E6: 15.14 | F6: 504.23M | G6: =B6/B5-1 -> 0.051816958
A7: 45200 | B7: 15.91 | C7: 15.51 | D7: 15.96 | E7: 15.47 | F7: 384.10M | G7: =B7/B6-1 -> 0.017914267
A8: 45231 | B8: 16 | C8: 15.84 | D8: 16.03 | E8: 15.56 | F8: 353.28M | G8: =B8/B7-1 -> 0.0056568196
A9: 45261 | B9: 16.51 | C9: 16.1 | D9: 16.64 | E9: 15.49 | F9: 551.41M | G9: =B9/B8-1 -> 0.031875
A10: 01/13/2023 | B10: 16.9 | C10: 16.28 | D10: 16.92 | E10: 16.17 | F10: 447.29M | G10: =B10/B9-1 -> 0.023622047
A11: 01/17/2023 | B11: 17.7 | C11: 16.9 | D11: 17.73 | E11: 16.9 | F11: 511.10M | G11: =B11/B10-1 -> 0.047337278
A12: 01/18/2023 | B12: 17.38 | C12: 17.67 | D12: 17.87 | E12: 17.28 | F12: 439.62M | G12: =B12/B11-1 -> -0.018079096
A13: 01/19/2023 | B13: 16.76 | C13: 17.04 | D13: 17.2 | E13: 16.73 | F13: 452.93M | G13: =B13/B12-1 -> -0.035673188
A14: 01/20/2023 | B14: 17.84 | C14: 17.01 | D14: 17.86 | E14: 16.83 | F14: 564.97M | G14: =B14/B13-1 -> 0.064439141
A15: 01/23/2023 | B15: 19.19 | C15: 18.06 | D15: 19.25 | E15: 17.82 | F15: 655.16M | G15: =B15/B14-1 -> 0.075672646
A16: 01/24/2023 | B16: 19.26 | C16: 18.83 | D16: 19.5 | E16: 18.82 | F16: 496.20M | G16: =B16/B15-1 -> 0.0036477332
A17: 01/25/2023 | B17: 19.32 | C17: 18.91 | D17: 19.37 | E17: 18.58 | F17: 449.54M | G17: =B17/B16-1 -> 0.0031152648
A18: 01/26/2023 | B18: 19.8 | C18: 19.7 | D18: 20.17 | E18: 19.28 | F18: 489.54M | G18: =B18/B17-1 -> 0.02484472
A19: 01/27/2023 | B19: 20.36 | C19: 19.46 | D19: 20.63 | E19: 19.41 | F19: 542.14M | G19: =B19/B18-1 -> 0.028282828
A20: 01/30/2023 | B20: 19.16 | C20: 19.95 | D20: 20.14 | E20: 19.15 | F20: 488.61M | G20: =B20/B19-1 -> -0.058939096
A21: 01/31/2023 | B21: 19.54 | C21: 19.17 | D21: 19.69 | E21: 18.95 | F21: 498.02M | G21: =B21/B20-1 -> 0.019832985
A22: 44928 | B22: 20.94 | C22: 19.69 | D22: 21.19 | E22: 19.61 | F22: 660.48M | G22: =B22/B21-1 -> 0.071647902
A23: 44959 | B23: 21.71 | C23: 21 | D23: 21.95 | E23: 20.7 | F23: 564.28M | G23: =B23/B22-1 -> 0.036771729
A24: 44987 | B24: 21.1 | C24: 21 | D24: 21.74 | E24: 20.79 | F24: 429.37M | G24: =B24/B23-1 -> -0.028097651
A25: 45079 | B25: 21.09 | C25: 20.81 | D25: 21.57 | E25: 20.79 | F25: 452.20M | G25: =B25/B24-1 -> -0.00047393365
A26: 45109 | B26: 22.17 | C26: 21.38 | D26: 22.26 | E26: 21.15 | F26: 664.15M | G26: =B26/B25-1 -> 0.051209104
A27: 45140 | B27: 22.2 | C27: 22.39 | D27: 22.88 | E27: 22.01 | F27: 559.65M | G27: =B27/B26-1 -> 0.00135318
A28: 45171 | B28: 22.34 | C28: 22.61 | D28: 23.02 | E28: 22.12 | F28: 523.88M | G28: =B28/B27-1 -> 0.0063063063
A29: 45201 | B29: 21.26 | C29: 21.69 | D29: 22.08 | E29: 20.81 | F29: 550.74M | G29: =B29/B28-1 -> -0.048343778
A30: 02/13/2023 | B30: 21.79 | C30: 21.54 | D30: 22.05 | E30: 20.96 | F30: 474.92M | G30: =B30/B29-1 -> 0.024929445
A31: 02/14/2023 | B31: 22.97 | C31: 21.58 | D31: 23.05 | E31: 21.37 | F31: 675.47M | G31: =B31/B30-1 -> 0.054153281
A32: 02/15/2023 | B32: 22.76 | C32: 22.55 | D32: 22.85 | E32: 22.11 | F32: 421.19M | G32: =B32/B31-1 -> -0.0091423596
A33: 02/16/2023 | B33: 22 | C33: 22.13 | D33: 22.55 | E33: 21.93 | F33: 412.03M | G33: =B33/B32-1 -> -0.033391916
A34: 02/17/2023 | B34: 21.39 | C34: 21.63 | D34: 21.74 | E34: 20.98 | F34: 465.89M | G34: =B34/B33-1 -> -0.027727273
A35: 02/21/2023 | B35: 20.66 | C35: 21 | D35: 21.49 | E35: 20.62 | F35: 410.02M | G35: =B35/B34-1 -> -0.034128097
A36: 02/22/2023 | B36: 20.75 | C36: 20.71 | D36: 21.1 | E36: 20.42 | F36: 513.18M | G36: =B36/B35-1 -> 0.0043562439
A37: 02/23/2023 | B37: 23.66 | C37: 23.44 | D37: 23.89 | E37: 23.02 | F37: 1.12B | G37: =B37/B36-1 -> 0.14024096
A38: 02/24/2023 | B38: 23.29 | C38: 23.23 | D38: 23.47 | E38: 22.95 | F38: 589.72M | G38: =B38/B37-1 -> -0.015638208
A39: 02/27/2023 | B39: 23.5 | C39: 23.67 | D39: 23.88 | E39: 23.45 | F39: 452.99M | G39: =B39/B38-1 -> 0.0090167454
A40: 02/28/2023 | B40: 23.22 | C40: 23.37 | D40: 23.83 | E40: 23.21 | F40: 455.96M | G40: =B40/B39-1 -> -0.011914894
...

Sheet Henkel ST Stock Price History (
A1: Date | B1: Price | C1: Open | D1: High | E1: Low | F1: Vol.
A2: 44958 | B2: 60.3 | C2: 60.2 | D2: 60.45 | E2: 60 | F2: 30.97K
A3: 44986 | B3: 61.05 | C3: 60.1 | D3: 61.3 | E3: 60.05 | F3: 60.27K | G3: =B3/B2-1 -> 0.012437811
A4: 45017 | B4: 61.4 | C4: 61.3 | D4: 61.75 | E4: 61.05 | F4: 82.24K | G4: =B4/B3-1 -> 0.0057330057
A5: 45047 | B5: 62.25 | C5: 61.3 | D5: 62.6 | E5: 61.3 | F5: 69.40K | G5: =B5/B4-1 -> 0.013843648
A6: 45078 | B6: 61.4 | C6: 62.3 | D6: 62.55 | E6: 61 | F6: 85.30K | G6: =B6/B5-1 -> -0.013654618
A7: 45170 | B7: 61.5 | C7: 61.3 | D7: 61.7 | E7: 59.55 | F7: 112.86K | G7: =B7/B6-1 -> 0.0016286645
A8: 45200 | B8: 61.05 | C8: 61.45 | D8: 61.6 | E8: 60.65 | F8: 91.14K | G8: =B8/B7-1 -> -0.0073170732
A9: 45231 | B9: 61.5 | C9: 61 | D9: 61.55 | E9: 60.65 | F9: 111.23K | G9: =B9/B8-1 -> 0.0073710074
A10: 45261 | B10: 61 | C10: 61 | D10: 61.55 | E10: 60.65 | F10: 117.27K | G10: =B10/B9-1 -> -0.0081300813
A11: 01/13/2023 | B11: 61.1 | C11: 61 | D11: 61.55 | E11: 60.8 | F11: 96.86K | G11: =B11/B10-1 -> 0.0016393443
A12: 01/16/2023 | B12: 61.65 | C12: 61.2 | D12: 62.15 | E12: 61.15 | F12: 52.49K | G12: =B12/B11-1 -> 0.0090016367
A13: 01/17/2023 | B13: 62 | C13: 61.6 | D13: 62.65 | E13: 61.4 | F13: 129.83K | G13: =B13/B12-1 -> 0.0056772101
A14: 01/18/2023 | B14: 62.3 | C14: 62.05 | D14: 63.1 | E14: 62.05 | F14: 133.93K | G14: =B14/B13-1 -> 0.0048387097
A15: 01/19/2023 | B15: 61.25 | C15: 62.1 | D15: 62.2 | E15: 60.95 | F15: 114.77K | G15: =B15/B14-1 -> -0.016853933
A16: 01/20/2023 | B16: 61.3 | C16: 61.25 | D16: 61.65 | E16: 61 | F16: 83.94K | G16: =B16/B15-1 -> 0.00081632653
A17: 01/23/2023 | B17: 60.9 | C17: 61.5 | D17: 61.6 | E17: 60.8 | F17: 41.19K | G17: =B17/B16-1 -> -0.0065252855
A18: 01/24/2023 | B18: 60.85 | C18: 60.85 | D18: 61 | E18: 60.25 | F18: 48.84K | G18: =B18/B17-1 -> -0.00082101806
A19: 01/25/2023 | B19: 61.15 | C19: 60.65 | D19: 61.2 | E19: 60.65 | F19: 49.85K | G19: =B19/B18-1 -> 0.0049301561
A20: 01/26/2023 | B20: 60.9 | C20: 61.4 | D20: 61.5 | E20: 60.6 | F20: 92.69K | G20: =B20/B19-1 -> -0.0040883074
A21: 01/27/2023 | B21: 60.8 | C21: 60.85 | D21: 61.05 | E21: 60.45 | F21: 93.72K | G21: =B21/B20-1 -> -0.0016420361
A22: 01/30/2023 | B22: 61.25 | C22: 60.65 | D22: 61.4 | E22: 60.4 | F22: 86.43K | G22: =B22/B21-1 -> 0.0074013158
A23: 01/31/2023 | B23: 61.3 | C23: 61.15 | D23: 61.4 | E23: 61 | F23: 91.28K | G23: =B23/B22-1 -> 0.00081632653
A24: 44928 | B24: 61.5 | C24: 61.5 | D24: 61.5 | E24: 60.95 | F24: 64.35K | G24: =B24/B23-1 -> 0.0032626427
A25: 44959 | B25: 61.45 | C25: 61.9 | D25: 61.9 | E25: 61.1 | F25: 62.26K | G25: =B25/B24-1 -> -0.00081300813
A26: 44987 | B26: 61.5 | C26: 61.45 | D26: 61.5 | E26: 61.15 | F26: 88.97K | G26: =B26/B25-1 -> 0.00081366965
A27: 45079 | B27: 61.25 | C27: 61.25 | D27: 61.45 | E27: 60.8 | F27: 49.25K | G27: =B27/B26-1 -> -0.0040650407
A28: 45109 | B28: 61.35 | C28: 61 | D28: 61.35 | E28: 60.85 | F28: 90.42K | G28: =B28/B27-1 -> 0.0016326531
A29: 45140 | B29: 62 | C29: 61.45 | D29: 62.15 | E29: 61.25 | F29: 105.74K | G29: =B29/B28-1 -> 0.010594947
A30: 45171 | B30: 61.95 | C30: 61.75 | D30: 62.25 | E30: 61.75 | F30: 97.74K | G30: =B30/B29-1 -> -0.00080645161
A31: 45201 | B31: 62.3 | C31: 61.8 | D31: 62.4 | E31: 61.65 | F31: 94.90K | G31: =B31/B30-1 -> 0.0056497175
A32: 02/13/2023 | B32: 63.45 | C32: 62.35 | D32: 63.45 | E32: 62.35 | F32: 71.15K | G32: =B32/B31-1 -> 0.018459069
A33: 02/14/2023 | B33: 63.65 | C33: 63.05 | D33: 63.95 | E33: 63.05 | F33: 89.48K | G33: =B33/B32-1 -> 0.0031520883
A34: 02/15/2023 | B34: 63.9 | C34: 63.75 | D34: 64.05 | E34: 63.6 | F34: 55.63K | G34: =B34/B33-1 -> 0.0039277298
A35: 02/16/2023 | B35: 63.55 | C35: 63.75 | D35: 63.95 | E35: 62.85 | F35: 51.02K | G35: =B35/B34-1 -> -0.0054773083
A36: 02/17/2023 | B36: 64.1 | C36: 63.2 | D36: 64.15 | E36: 63.05 | F36: 54.00K | G36: =B36/B35-1 -> 0.0086546027
A37: 02/20/2023 | B37: 64.5 | C37: 64.25 | D37: 64.5 | E37: 63.85 | F37: 27.25K | G37: =B37/B36-1 -> 0.0062402496
A38: 02/21/2023 | B38: 64.85 | C38: 64.45 | D38: 65 | E38: 64.35 | F38: 55.57K | G38: =B38/B37-1 -> 0.0054263566
A39: 02/22/2023 | B39: 65.8 | C39: 64.75 | D39: 65.95 | E39: 64.7 | F39: 65.73K | G39: =B39/B38-1 -> 0.01464919
A40: 02/23/2023 | B40: 65.15 | C40: 65.75 | D40: 65.9 | E40: 65.1 | F40: 57.58K | G40: =B40/B39-1 -> -0.0098784195
...
