Workbook

Sheet Acciones
A1: Fecha | B1: AGUA.MX | C1: MARA.MX | D1: NKE.MX | E1: TEAKCPO.MX
A2: 44998 | B2: 26.345398 | C2: 127 | D2: 2213.1638 | E2: 3.9000001
A3: 44999 | B3: 26.770027 | C3: 131.98 | D3: 2186.2458 | E3: 3.9000001
A4: 45000 | B4: 25.809998 | C4: 133 | D4: 2238.4844 | E4: 3.6900001
A5: 45001 | B5: 25.708458 | C5: 143.7 | D5: 2251.0464 | E5: 3.9000001
A6: 45002 | B6: 25.56999 | C6: 155 | D6: 2250.7966 | E6: 3.9000001
A7: 45006 | B7: 24.960743 | C7: 165.06 | D7: 2333.1326 | E7: 3.75
A8: 45007 | B8: 25.293058 | C8: 144.59 | D8: 2223.1321 | E8: 3.7
A9: 45008 | B9: 24.517651 | C9: 157.72 | D9: 2233.1013 | E9: 3.5999999
A10: 45009 | B10: 24.94228 | C10: 144.52 | D10: 2216.6531 | E10: 3.7
A11: 45012 | B11: 25.182289 | C11: 132.58 | D11: 2160.8245 | E11: 3.7
A12: 45013 | B12: 25.643839 | C12: 132.75 | D12: 2134.446 | E12: 3.7
A13: 45014 | B13: 25.080748 | C13: 144.31 | D13: 2162.3203 | E13: 3.6800001
... A751: 46090 | B751: 10.91 | C751: 152.14999 | D751: 998.35999 | E751: 0.13

Sheet Rendimientos
A1: =Acciones!A1 -> Fecha | B1: AGUAR | C1: MARAR | D1: NKER | E1: TEAKCPOR
A2: =Acciones!A3 -> 44999 | B2: =Acciones!B3/Acciones!B2 -1 -> 0.016117776 | C2: =Acciones!C3/Acciones!C2 -1 -> 0.039212565 | D2: =Acciones!D3/Acciones!D2 -1 -> -0.012162664 | E2: =Acciones!E3/Acciones!E2 -1 -> 0
A3: =Acciones!A4 -> 45000 | B3: =Acciones!B4/Acciones!B3 -1 -> -0.035862108 | C3: =Acciones!C4/Acciones!C3 -1 -> 0.0077284763 | D3: =Acciones!D4/Acciones!D3 -1 -> 0.023894168 | E3: =Acciones!E4/Acciones!E3 -1 -> -0.053846162
A4: =Acciones!A5 -> 45001 | B4: =Acciones!B5/Acciones!B4 -1 -> -0.0039341194 | C4: =Acciones!C5/Acciones!C4 -1 -> 0.080451105 | D4: =Acciones!D5/Acciones!D4 -1 -> 0.005611838 | E4: =Acciones!E5/Acciones!E4 -1 -> 0.056910579
A5: =Acciones!A6 -> 45002 | B5: =Acciones!B6/Acciones!B5 -1 -> -0.0053860791 | C5: =Acciones!C6/Acciones!C5 -1 -> 0.07863607 | D5: =Acciones!D6/Acciones!D5 -1 -> -0.00011095101 | E5: =Acciones!E6/Acciones!E5 -1 -> 0
A6: =Acciones!A7 -> 45006 | B6: =Acciones!B7/Acciones!B6 -1 -> -0.02382665 | C6: =Acciones!C7/Acciones!C6 -1 -> 0.06490321 | D6: =Acciones!D7/Acciones!D6 -1 -> 0.036580798 | E6: =Acciones!E7/Acciones!E6 -1 -> -0.038461562
A7: =Acciones!A8 -> 45007 | B7: =Acciones!B8/Acciones!B7 -1 -> 0.013313524 | C7: =Acciones!C8/Acciones!C7 -1 -> -0.12401552 | D7: =Acciones!D8/Acciones!D7 -1 -> -0.047147123 | E7: =Acciones!E8/Acciones!E7 -1 -> -0.013333321
A8: =Acciones!A9 -> 45008 | B8: =Acciones!B9/Acciones!B8 -1 -> -0.030656941 | C8: =Acciones!C9/Acciones!C8 -1 -> 0.090808529 | D8: =Acciones!D9/Acciones!D8 -1 -> 0.0044843212 | E8: =Acciones!E9/Acciones!E8 -1 -> -0.027027065
A9: =Acciones!A10 -> 45009 | B9: =Acciones!B10/Acciones!B9 -1 -> 0.017319327 | C9: =Acciones!C10/Acciones!C9 -1 -> -0.0836926 | D9: =Acciones!D10/Acciones!D9 -1 -> -0.0073656498 | E9: =Acciones!E10/Acciones!E9 -1 -> 0.027777818
A10: =Acciones!A11 -> 45012 | B10: =Acciones!B11/Acciones!B10 -1 -> 0.009622589 | C10: =Acciones!C11/Acciones!C10 -1 -> -0.082618337 | D10: =Acciones!D11/Acciones!D10 -1 -> -0.025185995 | E10: =Acciones!E11/Acciones!E10 -1 -> 0
A11: =Acciones!A12 -> 45013 | B11: =Acciones!B12/Acciones!B11 -1 -> 0.018328348 | C11: =Acciones!C12/Acciones!C11 -1 -> 0.0012822309 | D11: =Acciones!D12/Acciones!D11 -1 -> -0.012207571 | E11: =Acciones!E12/Acciones!E11 -1 -> 0
A12: =Acciones!A13 -> 45014 | B12: =Acciones!B13/Acciones!B12 -1 -> -0.021958151 | C12: =Acciones!C13/Acciones!C12 -1 -> 0.087080961 | D12: =Acciones!D13/Acciones!D12 -1 -> 0.013059251 | E12: =Acciones!E13/Acciones!E12 -1 -> -0.0054054002
A13: =Acciones!A14 -> 45015 | B13: =Acciones!B14/Acciones!B13 -1 -> 0.015826263 | C13: =Acciones!C14/Acciones!C13 -1 -> -0.033331007 | D13: =Acciones!D14/Acciones!D13 -1 -> 0 | E13: =Acciones!E14/Acciones!E13 -1 -> -0.043478283
... A750: =Acciones!A751 -> 46090 | B750: =Acciones!B751/Acciones!B750 -1 -> -0.0036529646 | C750: =Acciones!C751/Acciones!C750 -1 -> 0.072082834 | D750: =Acciones!D751/Acciones!D750 -1 -> -0.016830003 | E750: =Acciones!E751/Acciones!E750 -1 -> -0.051094887

Sheet Estadísticas Descriptivas
A1: Rendimientos diarios AGUA | D1: Rendimientos diarios MARA | G1: Rendimientos diarios NKE | J1: Rendimientos diarios TEAKCPO
A3: Media | B3: -0.00092002627 | D3: Media | E3: 0.0020688337 | G3: Media | H3: -0.00079331759 | J3: Media | K3: -0.0026640814
A4: Error típico | B4: 0.00082702283 | D4: Error típico | E4: 0.0022358086 | G4: Error típico | H4: 0.00083884472 | J4: Error típico | K4: 0.0024755651
A5: Mediana | B5: -0.00083683925 | D5: Mediana | E5: -0.0023490053 | G5: Mediana | H5: -0.0016666943 | J5: Mediana | K5: 0
A6: Desviación estándar | B6: 0.022633849 | D6: Desviación estándar | E6: 0.061189306 | G6: Desviación estándar | H6: 0.022957388 | J6: Desviación estándar | K6: 0.067750931
A7: Varianza de la muestra | B7: 0.00051229111 | D7: Varianza de la muestra | E7: 0.0037441311 | G7: Varianza de la muestra | H7: 0.00052704169 | J7: Varianza de la muestra | K7: 0.0045901886
A8: Curtosis | B8: 1.8316632 | D8: Curtosis | E8: 2.3198503 | G8: Curtosis | H8: 15.793518 | J8: Curtosis | K8: 98.131932
A9: Coeficiente de asimetría | B9: -0.0026089753 | D9: Coeficiente de asimetría | E9: 0.70266252 | G9: Coeficiente de asimetría | H9: -1.0394642 | J9: Coeficiente de asimetría | K9: 7.1278316
A10: Rango | B10: 0.19322325 | D10: Rango | E10: 0.4997755 | G10: Rango | H10: 0.36001505 | J10: Rango | K10: 1.3109718
A11: Mínimo | B11: -0.10172421 | D11: Mínimo | E11: -0.18072456 | G11: Mínimo | H11: -0.20375074 | J11: Mínimo | K11: -0.2670157
A12: Máximo | B12: 0.091499042 | D12: Máximo | E12: 0.31905095 | G12: Máximo | H12: 0.15626432 | J12: Máximo | K12: 1.0439561
A13: Suma | B13: -0.68909967 | D13: Suma | E13: 1.5495564 | G13: Suma | H13: -0.59419488 | J13: Suma | K13: -1.995397
A14: Cuenta | B14: 749 | D14: Cuenta | E14: 749 | G14: Cuenta | H14: 749 | J14: Cuenta | K14: 749
A15: Confidence Level(95.0%) | B15: 0.001623562 | D15: Confidence Level(95.0%) | E15: 0.0043892064 | G15: Confidence Level(95.0%) | H15: 0.0016467701 | J15: Confidence Level(95.0%) | K15: 0.0048598822

Sheet Portafolio
A1: =Acciones!A1 -> Fecha | B1: AGUAR | C1: MARAR | D1: NKER | E1: TEAKCPOR | F1: Rendimiento Portafolio | G1: Diferencia Portafolio | H1: Diferencia % Portafolio | J1: pesos
F2: =J6 -> 28500 | G2: =F2-$J$6 -> 0 | H2: =(F2/$J$6)-1 -> 0 | J2: 3500 | K2: Agua
A3: =Acciones!A3 -> 44999 | B3: =Acciones!B3/Acciones!B2 -> 1.0161178 | C3: =Acciones!C3/Acciones!C2 -> 1.0392126 | D3: =Acciones!D3/Acciones!D2 -> 0.98783734 | E3: =Acciones!E3/Acciones!E2 -> 1 | F3: =$J$2*B3+$J$3*C3+$J$4*D3+$J$5*E3 -> 28807.305 | G3: =F3-$J$6 -> 307.30494 | H3: =(F3/$J$6)-1 -> 0.010782629 | J3: 9500 | K3: Mara
A4: =Acciones!A4 -> 45000 | B4: =Acciones!B4/Acciones!B3 -> 0.96413789 | C4: =Acciones!C4/Acciones!C3 -> 1.0077285 | D4: =Acciones!D4/Acciones!D3 -> 1.0238942 | E4: =Acciones!E4/Acciones!E3 -> 0.94615384 | F4: =$J$2*B4+$J$3*C4+$J$4*D4+$J$5*E4 -> 28390.691 | G4: =F4-$J$6 -> -109.30907 | H4: =(F4/$J$6)-1 -> -0.0038354058 | J4: 10000 | K4: Nke
A5: =Acciones!A5 -> 45001 | B5: =Acciones!B5/Acciones!B4 -> 0.99606588 | C5: =Acciones!C5/Acciones!C4 -> 1.0804511 | D5: =Acciones!D5/Acciones!D4 -> 1.0056118 | E5: =Acciones!E5/Acciones!E4 -> 1.0569106 | F5: =$J$2*B5+$J$3*C5+$J$4*D5+$J$5*E5 -> 29619.643 | G5: =F5-$J$6 -> 1119.6426 | H5: =(F5/$J$6)-1 -> 0.039285707 | J5: 5500 | K5: Teakcpo
A6: =Acciones!A6 -> 45002 | B6: =Acciones!B6/Acciones!B5 -> 0.99461392 | C6: =Acciones!C6/Acciones!C5 -> 1.0786361 | D6: =Acciones!D6/Acciones!D5 -> 0.99988905 | E6: =Acciones!E6/Acciones!E5 -> 1 | F6: =$J$2*B6+$J$3*C6+$J$4*D6+$J$5*E6 -> 29227.082 | G6: =F6-$J$6 -> 727.08188 | H6: =(F6/$J$6)-1 -> 0.025511645 | J6: =SUM(J2:J5) -> 28500
A7: =Acciones!A7 -> 45006 | B7: =Acciones!B7/Acciones!B6 -> 0.97617335 | C7: =Acciones!C7/Acciones!C6 -> 1.0649032 | D7: =Acciones!D7/Acciones!D6 -> 1.0365808 | E7: =Acciones!E7/Acciones!E6 -> 0.96153844 | F7: =$J$2*B7+$J$3*C7+$J$4*D7+$J$5*E7 -> 29187.457 | G7: =F7-$J$6 -> 687.45661 | H7: =(F7/$J$6)-1 -> 0.024121285
A8: =Acciones!A8 -> 45007 | B8: =Acciones!B8/Acciones!B7 -> 1.0133135 | C8: =Acciones!C8/Acciones!C7 -> 0.87598448 | D8: =Acciones!D8/Acciones!D7 -> 0.95285288 | E8: =Acciones!E8/Acciones!E7 -> 0.98666668 | F8: =$J$2*B8+$J$3*C8+$J$4*D8+$J$5*E8 -> 26823.645 | G8: =F8-$J$6 -> -1676.3546 | H8: =(F8/$J$6)-1 -> -0.058819459
A9: =Acciones!A9 -> 45008 | B9: =Acciones!B9/Acciones!B8 -> 0.96934306 | C9: =Acciones!C9/Acciones!C8 -> 1.0908085 | D9: =Acciones!D9/Acciones!D8 -> 1.0044843 | E9: =Acciones!E9/Acciones!E8 -> 0.97297293 | F9: =$J$2*B9+$J$3*C9+$J$4*D9+$J$5*E9 -> 29151.576 | G9: =F9-$J$6 -> 651.57609 | H9: =(F9/$J$6)-1 -> 0.022862319
A10: =Acciones!A10 -> 45009 | B10: =Acciones!B10/Acciones!B9 -> 1.0173193 | C10: =Acciones!C10/Acciones!C9 -> 0.9163074 | D10: =Acciones!D10/Acciones!D9 -> 0.99263435 | E10: =Acciones!E10/Acciones!E9 -> 1.0277778 | F10: =$J$2*B10+$J$3*C10+$J$4*D10+$J$5*E10 -> 27844.659 | G10: =F10-$J$6 -> -655.34055 | H10: =(F10/$J$6)-1 -> -0.022994405
A11: =Acciones!A11 -> 45012 | B11: =Acciones!B11/Acciones!B10 -> 1.0096226 | C11: =Acciones!C11/Acciones!C10 -> 0.91738166 | D11: =Acciones!D11/Acciones!D10 -> 0.97481401 | E11: =Acciones!E11/Acciones!E10 -> 1 | F11: =$J$2*B11+$J$3*C11+$J$4*D11+$J$5*E11 -> 27496.945 | G11: =F11-$J$6 -> -1003.0551 | H11: =(F11/$J$6)-1 -> -0.035194915
A12: =Acciones!A12 -> 45013 | B12: =Acciones!B12/Acciones!B11 -> 1.0183283 | C12: =Acciones!C12/Acciones!C11 -> 1.0012822 | D12: =Acciones!D12/Acciones!D11 -> 0.98779243 | E12: =Acciones!E12/Acciones!E11 -> 1 | F12: =$J$2*B12+$J$3*C12+$J$4*D12+$J$5*E12 -> 28454.255 | G12: =F12-$J$6 -> -45.745298 | H12: =(F12/$J$6)-1 -> -0.0016050982
A13: =Acciones!A13 -> 45014 | B13: =Acciones!B13/Acciones!B12 -> 0.97804185 | C13: =Acciones!C13/Acciones!C12 -> 1.087081 | D13: =Acciones!D13/Acciones!D12 -> 1.0130593 | E13: =Acciones!E13/Acciones!E12 -> 0.9945946 | F13: =$J$2*B13+$J$3*C13+$J$4*D13+$J$5*E13 -> 29351.278 | G13: =F13-$J$6 -> 851.27841 | H13: =(F13/$J$6)-1 -> 0.029869418
A14: =Acciones!A14 -> 45015 | B14: =Acciones!B14/Acciones!B13 -> 1.0158263 | C14: =Acciones!C14/Acciones!C13 -> 0.96666899 | D14: =Acciones!D14/Acciones!D13 -> 1 | E14: =Acciones!E14/Acciones!E13 -> 0.95652172 | F14: =$J$2*B14+$J$3*C14+$J$4*D14+$J$5*E14 -> 27999.617 | G14: =F14-$J$6 -> -500.38321 | H14: =(F14/$J$6)-1 -> -0.017557305
A15: =Acciones!A15 -> 45016 | B15: =Acciones!B15/Acciones!B14 -> 1.0018115 | C15: =Acciones!C15/Acciones!C14 -> 1.1194982 | D15: =Acciones!D15/Acciones!D14 -> 1.0189025 | E15: =Acciones!E15/Acciones!E14 -> 1.0767045 | F15: =$J$2*B15+$J$3*C15+$J$4*D15+$J$5*E15 -> 30252.473 | G15: =F15-$J$6 -> 1752.4734 | H15: =(F15/$J$6)-1 -> 0.061490294
A16: =Acciones!A16 -> 45019 | B16: =Acciones!B16/Acciones!B15 -> 0.95370712 | C16: =Acciones!C16/Acciones!C15 -> 0.98482426 | D16: =Acciones!D16/Acciones!D15 -> 0.99383275 | E16: =Acciones!E16/Acciones!E15 -> 1.0290238 | F16: =$J$2*B16+$J$3*C16+$J$4*D16+$J$5*E16 -> 28291.764 | G16: =F16-$J$6 -> -208.23631 | H16: =(F16/$J$6)-1 -> -0.0073065372
A17: =Acciones!A17 -> 45020 | B17: =Acciones!B17/Acciones!B16 -> 1.0144102 | C17: =Acciones!C17/Acciones!C16 -> 1.0022756 | D17: =Acciones!D17/Acciones!D16 -> 1.0198645 | E17: =Acciones!E17/Acciones!E16 -> 1.0102564 | F17: =$J$2*B17+$J$3*C17+$J$4*D17+$J$5*E17 -> 28827.109 | G17: =F17-$J$6 -> 327.10899 | H17: =(F17/$J$6)-1 -> 0.011477508
A18: =Acciones!A18 -> 45021 | B18: =Acciones!B18/Acciones!B17 -> 0.99028044 | C18: =Acciones!C18/Acciones!C17 -> 0.93791766 | D18: =Acciones!D18/Acciones!D17 -> 1 | E18: =Acciones!E18/Acciones!E17 -> 1.0126903 | F18: =$J$2*B18+$J$3*C18+$J$4*D18+$J$5*E18 -> 27945.996 | G18: =F18-$J$6 -> -554.00379 | H18: =(F18/$J$6)-1 -> -0.019438729
... A751: =Acciones!A751 -> 46090 | B751: =Acciones!B751/Acciones!B750 -> 0.99634704 | C751: =Acciones!C751/Acciones!C750 -> 1.0720828 | D751: =Acciones!D751/Acciones!D750 -> 0.98317 | E751: =Acciones!E751/Acciones!E750 -> 0.94890511 | F751: =$J$2*B751+$J$3*C751+$J$4*D751+$J$5*E751 -> 28722.68 | G751: =F751-$J$6 -> 222.67964 | H751: =(F751/$J$6)-1 -> 0.0078133207

Sheet VAR HIST
A1: =Acciones!A1 -> Fecha | B1: Ganacias/ Perdidas
A2: =Acciones!A518 -> 45750 | B2: -3014.8088 | D2: Confianza = | E2: 0.975
A3: =Acciones!A709 -> 46029 | B3: -2052.0339 | D3: Cuantil = | E3: =COUNT(B2:B751)*(1-E2) -> 18.75
A4: =Acciones!A245 -> 45351 | B4: -1962.5552 | D4: VaR97.5%, 1 día (MXN) = | E4: =ABS(SMALL(B2:B751,E3)) -> 1380.0026
A5: =Acciones!A327 -> 45471 | B5: -1749.4664 | D5: VaR97.5%, 1 día (%P) = | E5: =E4/Portafolio!J6 -> 0.048421145
A6: =Acciones!A8 -> 45007 | B6: -1676.3546 | D6: CVaR97.5%, 1 día (MXN) = | E6: =ABS(AVERAGE(B2:B18)) -> 1670.9708
A7: =Acciones!A248 -> 45356 | B7: -1670.511 | D7: CVaR97.5%, 1 día (%P) = | E7: =E6/Portafolio!J6 -> 0.058630556
A8: =Acciones!A696 -> 46008 | B8: -1646.1716 | D8: N = | E8: 10
A9: =Acciones!A523 -> 45757 | B9: -1598.4475 | D9: VaR97.5%, 10 días = | E9: =E4*SQRT(E8) -> 4363.9515
A10: =Acciones!A729 -> 46058 | B10: -1519.1838 | D10: VaR97.5%, 10 días (%P) = | E10: =E9/Portafolio!J6 -> 0.1531211
A11: =Acciones!A212 -> 45303 | B11: -1490.8998
A12: =Acciones!A41 -> 45057 | B12: -1467.6898 | D12: Aplicación regulatoria:
A13: =Acciones!A501 -> 45726 | B13: -1446.2875 | D13: CapitalRiesgo de mercado (USD) = | E13: =3*E9 -> 13091.854
A14: =Acciones!A698 -> 46010 | B14: -1440.7393 | D14: CapitalRiesgo de mercado (%P) = | E14: =E13/Portafolio!J6 -> 0.45936331
A15: =Acciones!A292 -> 45422 | B15: -1439.9811
A16: =Acciones!A423 -> 45609 | B16: -1428.7621
A17: =Acciones!A426 -> 45615 | B17: -1404.0836
A18: =Acciones!A203 -> 45289 | B18: -1398.5284
A19: =Acciones!A537 -> 45782 | B19: -1380.0026
A20: =Acciones!A116 -> 45162 | B20: -1329.6059
A21: =Acciones!A521 -> 45755 | B21: -1318.1595
A22: =Acciones!A393 -> 45567 | B22: -1306.9811
A23: =Acciones!A654 -> 45946 | B23: -1269.8784
A24: =Acciones!A699 -> 46013 | B24: -1250.4894
A25: =Acciones!A750 -> 46087 | B25: -1234.1471
A26: =Acciones!A265 -> 45384 | B26: -1215.8637
A27: =Acciones!A374 -> 45538 | B27: -1214.4192
A28: =Acciones!A514 -> 45744 | B28: -1190.8533
A29: =Acciones!A255 -> 45365 | B29: -1188.5601
A30: =Acciones!A731 -> 46062 | B30: -1178.6017
A31: =Acciones!A144 -> 45202 | B31: -1147.9693
A32: =Acciones!A727 -> 46056 | B32: -1147.3127
A33: =Acciones!A27 -> 45036 | B33: -1144.0695
A34: =Acciones!A285 -> 45412 | B34: -1142.8146
A35: =Acciones!A446 -> 45644 | B35: -1141.9244
A36: =Acciones!A492 -> 45713 | B36: -1130.3942
A37: =Acciones!A260 -> 45373 | B37: -1116.8013
A38: =Acciones!A702 -> 46017 | B38: -1109.7657
A39: =Acciones!A718 -> 46042 | B39: -1105.0193
A40: =Acciones!A128 -> 45180 | B40: -1101.3047
...

Sheet VAR SM
A1: =Acciones!A1 -> Fecha | B1: =Acciones!B1 -> AGUA.MX | C1: =Acciones!C1 -> MARA.MX | D1: =Acciones!D1 -> NKE.MX | E1: =Acciones!E1 -> TEAKCPO.MX | H1: AGUA.MX | I1: MARA.MX | J1: NKE.MX | K1: TEAKCPO.MX | M1: Precios en t+1 simulados por MC
G2: m = | H2: =AVERAGE(B3:B751) -> -0.0011770545 | I2: =AVERAGE(C3:C751) -> 0.00024122797 | J2: =AVERAGE(D3:D751) -> -0.0010628364 | K2: =AVERAGE(E3:E751) -> -0.0045409846
A3: =Acciones!A3 -> 44999 | B3: =LN(Acciones!B3/Acciones!B2) -> 0.015989263 | C3: =LN(Acciones!C3/Acciones!C2) -> 0.038463277 | D3: =LN(Acciones!D3/Acciones!D2) -> -0.012237235 | E3: =LN(Acciones!E3/Acciones!E2) -> 0 | G3: s2 = | H3: =_xlfn.VAR.P(B3:B751) -> 0.00051368902 | I3: =_xlfn.VAR.P(C3:C751) -> 0.0036217287 | J3: =_xlfn.VAR.P(D3:D751) -> 0.00054498607 | K3: =_xlfn.VAR.P(E3:E751) -> 0.0034510053
A4: =Acciones!A4 -> 45000 | B4: =LN(Acciones!B4/Acciones!B3) -> -0.036520953 | C4: =LN(Acciones!C4/Acciones!C3) -> 0.0076987646 | D4: =LN(Acciones!D4/Acciones!D3) -> 0.02361317 | E4: =LN(Acciones!E4/Acciones!E3) -> -0.055350104 | G4: s = | H4: =_xlfn.STDEV.P(B3:B751) -> 0.022664709 | I4: =_xlfn.STDEV.P(C3:C751) -> 0.0601808 | J4: =_xlfn.STDEV.P(D3:D751) -> 0.023344937 | K4: =_xlfn.STDEV.P(E3:E751) -> 0.058745258 | M4: AGUA.MX | N4: MARA.MX | O4: NKE.MX | P4: TEAKCPO.MX | R4: Pt+1 | T4: DPt+1 | V4: DPt+1 (Ordenado)
A5: =Acciones!A5 -> 45001 | B5: =LN(Acciones!B5/Acciones!B4) -> -0.0039418784 | C5: =LN(Acciones!C5/Acciones!C4) -> 0.077378644 | D5: =LN(Acciones!D5/Acciones!D4) -> 0.0055961503 | E5: =LN(Acciones!E5/Acciones!E4) -> 0.055350104 | M5: =Acciones!$B$751*EXP((H$2-H$3/2)*(1)+H$4*_xlfn.NORM.S.INV(RAND())*SQRT(1)) -> 10.862615 | N5: =Acciones!$C$751*EXP((I$2-I$3/2)*(1)+I$4*_xlfn.NORM.S.INV(RAND())*SQRT(1)) -> 157.86614 | O5: =Acciones!$D$751*EXP((J$2-J$3/2)*(1)+J$4*_xlfn.NORM.S.INV(RAND())*SQRT(1)) -> 991.27931 | P5: =Acciones!$E$751*EXP((K$2-K$3/2)*(1)+K$4*_xlfn.NORM.S.INV(RAND())*SQRT(1)) -> 0.12805291 | R5: =M5/Acciones!$B$751*$I$10 + N5/Acciones!$C$751*$I$11 + O5/Acciones!$D$751*$I$12 + P5/Acciones!$D$751*$I$13 -> 23271.488 | T5: =R5-$I$14 -> -5228.5122 | V5: -7177.2788 | X5: Confianza = | Y5: 0.975
A6: =Acciones!A6 -> 45002 | B6: =LN(Acciones!B6/Acciones!B5) -> -0.0054006363 | C6: =LN(Acciones!C6/Acciones!C5) -> 0.075697345 | D6: =LN(Acciones!D6/Acciones!D5) -> -0.00011095716 | E6: =LN(Acciones!E6/Acciones!E5) -> 0 | M6: =Acciones!$B$751*EXP((H$2-H$3/2)*(1)+H$4*_xlfn.NORM.S.INV(RAND())*SQRT(1)) -> 10.399266 | N6: =Acciones!$C$751*EXP((I$2-I$3/2)*(1)+I$4*_xlfn.NORM.S.INV(RAND())*SQRT(1)) -> 145.42934 | O6: =Acciones!$D$751*EXP((J$2-J$3/2)*(1)+J$4*_xlfn.NORM.S.INV(RAND())*SQRT(1)) -> 982.43786 | P6: =Acciones!$E$751*EXP((K$2-K$3/2)*(1)+K$4*_xlfn.NORM.S.INV(RAND())*SQRT(1)) -> 0.13173127 | R6: =M6/Acciones!$B$751*$I$10 + N6/Acciones!$C$751*$I$11 + O6/Acciones!$D$751*$I$12 + P6/Acciones!$D$751*$I$13 -> 22257.769 | T6: =R6-$I$14 -> -6242.2306 | V6: -7156.1813 | X6: Cuantil = | Y6: =COUNT(V5:V753)*(1-Y5) -> 18.725
A7: =Acciones!A7 -> 45006 | B7: =LN(Acciones!B7/Acciones!B6) -> -0.024115096 | C7: =LN(Acciones!C7/Acciones!C6) -> 0.062883912 | D7: =LN(Acciones!D7/Acciones!D6) -> 0.035927603 | E7: =LN(Acciones!E7/Acciones!E6) -> -0.039220738 | M7: =Acciones!$B$751*EXP((H$2-H$3/2)*(1)+H$4*_xlfn.NORM.S.INV(RAND())*SQRT(1)) -> 10.398539 | N7: =Acciones!$C$751*EXP((I$2-I$3/2)*(1)+I$4*_xlfn.NORM.S.INV(RAND())*SQRT(1)) -> 148.47 | O7: =Acciones!$D$751*EXP((J$2-J$3/2)*(1)+J$4*_xlfn.NORM.S.INV(RAND())*SQRT(1)) -> 998.58253 | P7: =Acciones!$E$751*EXP((K$2-K$3/2)*(1)+K$4*_xlfn.NORM.S.INV(RAND())*SQRT(1)) -> 0.13635596 | R7: =M7/Acciones!$B$751*$I$10 + N7/Acciones!$C$751*$I$11 + O7/Acciones!$D$751*$I$12 + P7/Acciones!$D$751*$I$13 -> 22609.128 | T7: =R7-$I$14 -> -5890.8725 | V7: -7069.8757 | X7: VaR97.5%, 1 día = | Y7: =ABS(V24) -> 6710.4163 | Z7: =Y7/I$14 -> 0.2354532
A8: =Acciones!A8 -> 45007 | B8: =LN(Acciones!B8/Acciones!B7) -> 0.013225678 | C8: =LN(Acciones!C8/Acciones!C7) -> -0.1324069 | D8: =LN(Acciones!D8/Acciones!D7) -> -0.048294766 | E8: =LN(Acciones!E8/Acciones!E7) -> -0.013423007 | M8: =Acciones!$B$751*EXP((H$2-H$3/2)*(1)+H$4*_xlfn.NORM.S.INV(RAND())*SQRT(1)) -> 10.757926 | N8: =Acciones!$C$751*EXP((I$2-I$3/2)*(1)+I$4*_xlfn.NORM.S.INV(RAND())*SQRT(1)) -> 146.1477 | O8: =Acciones!$D$751*EXP((J$2-J$3/2)*(1)+J$4*_xlfn.NORM.S.INV(RAND())*SQRT(1)) -> 1039.9762 | P8: =Acciones!$E$751*EXP((K$2-K$3/2)*(1)+K$4*_xlfn.NORM.S.INV(RAND())*SQRT(1)) -> 0.13046658 | R8: =M8/Acciones!$B$751*$I$10 + N8/Acciones!$C$751*$I$11 + O8/Acciones!$D$751*$I$12 + P8/Acciones!$D$751*$I$13 -> 22994.004 | T8: =R8-$I$14 -> -5505.9959 | V8: -7035.184 | X8: CVaR97.5%, 1 día = | Y8: =ABS(AVERAGE(V5:V23)) -> 6864.8264 | Z8: =Y8/I$14 -> 0.2408711
A9: =Acciones!A9 -> 45008 | B9: =LN(Acciones!B9/Acciones!B8) -> -0.031136695 | C9: =LN(Acciones!C9/Acciones!C8) -> 0.086919191 | D9: =LN(Acciones!D9/Acciones!D8) -> 0.0044742966 | E9: =LN(Acciones!E9/Acciones!E8) -> -0.027399014 | I9: pesos | M9: =Acciones!$B$751*EXP((H$2-H$3/2)*(1)+H$4*_xlfn.NORM.S.INV(RAND())*SQRT(1)) -> 10.79583 | N9: =Acciones!$C$751*EXP((I$2-I$3/2)*(1)+I$4*_xlfn.NORM.S.INV(RAND())*SQRT(1)) -> 149.48651 | O9: =Acciones!$D$751*EXP((J$2-J$3/2)*(1)+J$4*_xlfn.NORM.S.INV(RAND())*SQRT(1)) -> 986.43044 | P9: =Acciones!$E$751*EXP((K$2-K$3/2)*(1)+K$4*_xlfn.NORM.S.INV(RAND())*SQRT(1)) -> 0.12253578 | R9: =M9/Acciones!$B$751*$I$10 + N9/Acciones!$C$751*$I$11 + O9/Acciones!$D$751*$I$12 + P9/Acciones!$D$751*$I$13 -> 22678.253 | T9: =R9-$I$14 -> -5821.7469 | V9: -7008.3068
A10: =Acciones!A10 -> 45009 | B10: =LN(Acciones!B10/Acciones!B9) -> 0.017171057 | C10: =LN(Acciones!C10/Acciones!C9) -> -0.087403381 | D10: =LN(Acciones!D10/Acciones!D9) -> -0.0073929101 | E10: =LN(Acciones!E10/Acciones!E9) -> 0.027399014 | I10: 3500 | J10: Agua | M10: =Acciones!$B$751*EXP((H$2-H$3/2)*(1)+H$4*_xlfn.NORM.S.INV(RAND())*SQRT(1)) -> 10.504801 | N10: =Acciones!$C$751*EXP((I$2-I$3/2)*(1)+I$4*_xlfn.NORM.S.INV(RAND())*SQRT(1)) -> 164.56063 | O10: =Acciones!$D$751*EXP((J$2-J$3/2)*(1)+J$4*_xlfn.NORM.S.INV(RAND())*SQRT(1)) -> 978.55196 | P10: =Acciones!$E$751*EXP((K$2-K$3/2)*(1)+K$4*_xlfn.NORM.S.INV(RAND())*SQRT(1)) -> 0.13004954 | R10: =M10/Acciones!$B$751*$I$10 + N10/Acciones!$C$751*$I$11 + O10/Acciones!$D$751*$I$12 + P10/Acciones!$D$751*$I$13 -> 23447.22 | T10: =R10-$I$14 -> -5052.7796 | V10: -6983.3482 | X10: VaR97.5%, 10 días = | Y10: =Y7*SQRT(10) -> 21220.2 | Z10: =Y10/I14 -> 0.74456841
A11: =Acciones!A11 -> 45012 | B11: =LN(Acciones!B11/Acciones!B10) -> 0.0095765868 | C11: =LN(Acciones!C11/Acciones!C10) -> -0.086231685 | D11: =LN(Acciones!D11/Acciones!D10) -> -0.02550859 | E11: =LN(Acciones!E11/Acciones!E10) -> 0 | I11: 9500 | J11: Mara | M11: =Acciones!$B$751*EXP((H$2-H$3/2)*(1)+H$4*_xlfn.NORM.S.INV(RAND())*SQRT(1)) -> 11.128043 | N11: =Acciones!$C$751*EXP((I$2-I$3/2)*(1)+I$4*_xlfn.NORM.S.INV(RAND())*SQRT(1)) -> 138.94431 | O11: =Acciones!$D$751*EXP((J$2-J$3/2)*(1)+J$4*_xlfn.NORM.S.INV(RAND())*SQRT(1)) -> 985.83777 | P11: =Acciones!$E$751*EXP((K$2-K$3/2)*(1)+K$4*_xlfn.NORM.S.INV(RAND())*SQRT(1)) -> 0.12333787 | R11: =M11/Acciones!$B$751*$I$10 + N11/Acciones!$C$751*$I$11 + O11/Acciones!$D$751*$I$12 + P11/Acciones!$D$751*$I$13 -> 22120.66 | T11: =R11-$I$14 -> -6379.3403 | V11: -6867.693 | X11: CapitalRiesgo de mercado = | Y11: =3*Y10 -> 63660.599 | Z11: =Y11/I14 -> 2.2337052
A12: =Acciones!A12 -> 45013 | B12: =LN(Acciones!B12/Acciones!B11) -> 0.018162408 | C12: =LN(Acciones!C12/Acciones!C11) -> 0.0012814095 | D12: =LN(Acciones!D12/Acciones!D11) -> -0.012282695 | E12: =LN(Acciones!E12/Acciones!E11) -> 0 | I12: 10000 | J12: Nke | M12: =Acciones!$B$751*EXP((H$2-H$3/2)*(1)+H$4*_xlfn.NORM.S.INV(RAND())*SQRT(1)) -> 11.076181 | N12: =Acciones!$C$751*EXP((I$2-I$3/2)*(1)+I$4*_xlfn.NORM.S.INV(RAND())*SQRT(1)) -> 155.4226 | O12: =Acciones!$D$751*EXP((J$2-J$3/2)*(1)+J$4*_xlfn.NORM.S.INV(RAND())*SQRT(1)) -> 981.49059 | P12: =Acciones!$E$751*EXP((K$2-K$3/2)*(1)+K$4*_xlfn.NORM.S.INV(RAND())*SQRT(1)) -> 0.12527375 | R12: =M12/Acciones!$B$751*$I$10 + N12/Acciones!$C$751*$I$11 + O12/Acciones!$D$751*$I$12 + P12/Acciones!$D$751*$I$13 -> 23089.367 | T12: =R12-$I$14 -> -5410.6325 | V12: -6817.3781
A13: =Acciones!A13 -> 45014 | B13: =LN(Acciones!B13/Acciones!B12) -> -0.022202819 | C13: =LN(Acciones!C13/Acciones!C12) -> 0.083496086 | D13: =LN(Acciones!D13/Acciones!D12) -> 0.012974715 | E13: =LN(Acciones!E13/Acciones!E12) -> -0.0054200622 | I13: 5500 | J13: Teakcpo | M13: =Acciones!$B$751*EXP((H$2-H$3/2)*(1)+H$4*_xlfn.NORM.S.INV(RAND())*SQRT(1)) -> 10.962348 | N13: =Acciones!$C$751*EXP((I$2-I$3/2)*(1)+I$4*_xlfn.NORM.S.INV(RAND())*SQRT(1)) -> 145.86869 | O13: =Acciones!$D$751*EXP((J$2-J$3/2)*(1)+J$4*_xlfn.NORM.S.INV(RAND())*SQRT(1)) -> 1033.2723 | P13: =Acciones!$E$751*EXP((K$2-K$3/2)*(1)+K$4*_xlfn.NORM.S.INV(RAND())*SQRT(1)) -> 0.14595222 | R13: =M13/Acciones!$B$751*$I$10 + N13/Acciones!$C$751*$I$11 + O13/Acciones!$D$751*$I$12 + P13/Acciones!$D$751*$I$13 -> 22975.1 | T13: =R13-$I$14 -> -5524.8996 | V13: -6799.5388
A14: =Acciones!A14 -> 45015 | B14: =LN(Acciones!B14/Acciones!B13) -> 0.015702334 | C14: =LN(Acciones!C14/Acciones!C13) -> -0.033899145 | D14: =LN(Acciones!D14/Acciones!D13) -> 0 | E14: =LN(Acciones!E14/Acciones!E13) -> -0.044451786 | I14: =SUM(I10:I13) -> 28500 | M14: =Acciones!$B$751*EXP((H$2-H$3/2)*(1)+H$4*_xlfn.NORM.S.INV(RAND())*SQRT(1)) -> 11.448308 | N14: =Acciones!$C$751*EXP((I$2-I$3/2)*(1)+I$4*_xlfn.NORM.S.INV(RAND())*SQRT(1)) -> 149.42897 | O14: =Acciones!$D$751*EXP((J$2-J$3/2)*(1)+J$4*_xlfn.NORM.S.INV(RAND())*SQRT(1)) -> 980.99881 | P14: =Acciones!$E$751*EXP((K$2-K$3/2)*(1)+K$4*_xlfn.NORM.S.INV(RAND())*SQRT(1)) -> 0.11007069 | R14: =M14/Acciones!$B$751*$I$10 + N14/Acciones!$C$751*$I$11 + O14/Acciones!$D$751*$I$12 + P14/Acciones!$D$751*$I$13 -> 22829.506 | T14: =R14-$I$14 -> -5670.4943 | V14: -6790.104
A15: =Acciones!A15 -> 45016 | B15: =LN(Acciones!B15/Acciones!B14) -> 0.0018099083 | C15: =LN(Acciones!C15/Acciones!C14) -> 0.11288054 | D15: =LN(Acciones!D15/Acciones!D14) -> 0.018726082 | E15: =LN(Acciones!E15/Acciones!E14) -> 0.073905025 | M15: =Acciones!$B$751*EXP((H$2-H$3/2)*(1)+H$4*_xlfn.NORM.S.INV(RAND())*SQRT(1)) -> 10.816685 | N15: =Acciones!$C$751*EXP((I$2-I$3/2)*(1)+I$4*_xlfn.NORM.S.INV(RAND())*SQRT(1)) -> 154.33237 | O15: =Acciones!$D$751*EXP((J$2-J$3/2)*(1)+J$4*_xlfn.NORM.S.INV(RAND())*SQRT(1)) -> 972.13861 | P15: =Acciones!$E$751*EXP((K$2-K$3/2)*(1)+K$4*_xlfn.NORM.S.INV(RAND())*SQRT(1)) -> 0.13955922 | R15: =M15/Acciones!$B$751*$I$10 + N15/Acciones!$C$751*$I$11 + O15/Acciones!$D$751*$I$12 + P15/Acciones!$D$751*$I$13 -> 22844.452 | T15: =R15-$I$14 -> -5655.5476 | V15: -6786.5662
A16: =Acciones!A16 -> 45019 | B16: =LN(Acciones!B16/Acciones!B15) -> -0.04739866 | C16: =LN(Acciones!C16/Acciones!C15) -> -0.015292069 | D16: =LN(Acciones!D16/Acciones!D15) -> -0.0061863464 | E16: =LN(Acciones!E16/Acciones!E15) -> 0.028610569 | M16: =Acciones!$B$751*EXP((H$2-H$3/2)*(1)+H$4*_xlfn.NORM.S.INV(RAND())*SQRT(1)) -> 10.557058 | N16: =Acciones!$C$751*EXP((I$2-I$3/2)*(1)+I$4*_xlfn.NORM.S.INV(RAND())*SQRT(1)) -> 156.21037 | O16: =Acciones!$D$751*EXP((J$2-J$3/2)*(1)+J$4*_xlfn.NORM.S.INV(RAND())*SQRT(1)) -> 1028.4205 | P16: =Acciones!$E$751*EXP((K$2-K$3/2)*(1)+K$4*_xlfn.NORM.S.INV(RAND())*SQRT(1)) -> 0.12638706 | R16: =M16/Acciones!$B$751*$I$10 + N16/Acciones!$C$751*$I$11 + O16/Acciones!$D$751*$I$12 + P16/Acciones!$D$751*$I$13 -> 23442.092 | T16: =R16-$I$14 -> -5057.9077 | V16: -6781.0787
A17: =Acciones!A17 -> 45020 | B17: =LN(Acciones!B17/Acciones!B16) -> 0.014307351 | C17: =LN(Acciones!C17/Acciones!C16) -> 0.0022730378 | D17: =LN(Acciones!D17/Acciones!D16) -> 0.019669746 | E17: =LN(Acciones!E17/Acciones!E16) -> 0.01020416 | M17: =Acciones!$B$751*EXP((H$2-H$3/2)*(1)+H$4*_xlfn.NORM.S.INV(RAND())*SQRT(1)) -> 10.817773 | N17: =Acciones!$C$751*EXP((I$2-I$3/2)*(1)+I$4*_xlfn.NORM.S.INV(RAND())*SQRT(1)) -> 172.63576 | O17: =Acciones!$D$751*EXP((J$2-J$3/2)*(1)+J$4*_xlfn.NORM.S.INV(RAND())*SQRT(1)) -> 980.45986 | P17: =Acciones!$E$751*EXP((K$2-K$3/2)*(1)+K$4*_xlfn.NORM.S.INV(RAND())*SQRT(1)) -> 0.12747861 | R17: =M17/Acciones!$B$751*$I$10 + N17/Acciones!$C$751*$I$11 + O17/Acciones!$D$751*$I$12 + P17/Acciones!$D$751*$I$13 -> 24070.918 | T17: =R17-$I$14 -> -4429.0819 | V17: -6765.4781
A18: =Acciones!A18 -> 45021 | B18: =LN(Acciones!B18/Acciones!B17) -> -0.0097671033 | C18: =LN(Acciones!C18/Acciones!C17) -> -0.064093115 | D18: =LN(Acciones!D18/Acciones!D17) -> 0 | E18: =LN(Acciones!E18/Acciones!E17) -> 0.012610495 | M18: =Acciones!$B$751*EXP((H$2-H$3/2)*(1)+H$4*_xlfn.NORM.S.INV(RAND())*SQRT(1)) -> 11.061136 | N18: =Acciones!$C$751*EXP((I$2-I$3/2)*(1)+I$4*_xlfn.NORM.S.INV(RAND())*SQRT(1)) -> 158.97203 | O18: =Acciones!$D$751*EXP((J$2-J$3/2)*(1)+J$4*_xlfn.NORM.S.INV(RAND())*SQRT(1)) -> 1013.2068 | P18: =Acciones!$E$751*EXP((K$2-K$3/2)*(1)+K$4*_xlfn.NORM.S.INV(RAND())*SQRT(1)) -> 0.13195324 | R18: =M18/Acciones!$B$751*$I$10 + N18/Acciones!$C$751*$I$11 + O18/Acciones!$D$751*$I$12 + P18/Acciones!$D$751*$I$13 -> 23623.881 | T18: =R18-$I$14 -> -4876.1188 | V18: -6757.314
A19: =Acciones!A19 -> 45026 | B19: =LN(Acciones!B19/Acciones!B18) -> 0.013126055 | C19: =LN(Acciones!C19/Acciones!C18) -> 0.12426361 | D19: =LN(Acciones!D19/Acciones!D18) -> 0.047930877 | E19: =LN(Acciones!E19/Acciones!E18) -> -0.010075642 | M19: =Acciones!$B$751*EXP((H$2-H$3/2)*(1)+H$4*_xlfn.NORM.S.INV(RAND())*SQRT(1)) -> 11.045443 | N19: =Acciones!$C$751*EXP((I$2-I$3/2)*(1)+I$4*_xlfn.NORM.S.INV(RAND())*SQRT(1)) -> 154.40792 | O19: =Acciones!$D$751*EXP((J$2-J$3/2)*(1)+J$4*_xlfn.NORM.S.INV(RAND())*SQRT(1)) -> 991.22669 | P19: =Acciones!$E$751*EXP((K$2-K$3/2)*(1)+K$4*_xlfn.NORM.S.INV(RAND())*SQRT(1)) -> 0.13781491 | R19: =M19/Acciones!$B$751*$I$10 + N19/Acciones!$C$751*$I$11 + O19/Acciones!$D$751*$I$12 + P19/Acciones!$D$751*$I$13 -> 23113.742 | T19: =R19-$I$14 -> -5386.2584 | V19: -6738.8966
A20: =Acciones!A20 -> 45027 | B20: =LN(Acciones!B20/Acciones!B19) -> 0.041596603 | C20: =LN(Acciones!C20/Acciones!C19) -> 0.13338631 | D20: =LN(Acciones!D20/Acciones!D19) -> -0.048645263 | E20: =LN(Acciones!E20/Acciones!E19) -> -0.0025348532 | M20: =Acciones!$B$751*EXP((H$2-H$3/2)*(1)+H$4*_xlfn.NORM.S.INV(RAND())*SQRT(1)) -> 10.561838 | N20: =Acciones!$C$751*EXP((I$2-I$3/2)*(1)+I$4*_xlfn.NORM.S.INV(RAND())*SQRT(1)) -> 162.23451 | O20: =Acciones!$D$751*EXP((J$2-J$3/2)*(1)+J$4*_xlfn.NORM.S.INV(RAND())*SQRT(1)) -> 1007.2314 | P20: =Acciones!$E$751*EXP((K$2-K$3/2)*(1)+K$4*_xlfn.NORM.S.INV(RAND())*SQRT(1)) -> 0.14705877 | R20: =M20/Acciones!$B$751*$I$10 + N20/Acciones!$C$751*$I$11 + O20/Acciones!$D$751*$I$12 + P20/Acciones!$D$751*$I$13 -> 23607.639 | T20: =R20-$I$14 -> -4892.3613 | V20: -6735.2981
A21: =Acciones!A21 -> 45028 | B21: =LN(Acciones!B21/Acciones!B20) -> -0.031956253 | C21: =LN(Acciones!C21/Acciones!C20) -> -0.049306145 | D21: =LN(Acciones!D21/Acciones!D20) -> 0.014018615 | E21: =LN(Acciones!E21/Acciones!E20) -> 0 | M21: =Acciones!$B$751*EXP((H$2-H$3/2)*(1)+H$4*_xlfn.NORM.S.INV(RAND())*SQRT(1)) -> 10.592653 | N21: =Acciones!$C$751*EXP((I$2-I$3/2)*(1)+I$4*_xlfn.NORM.S.INV(RAND())*SQRT(1)) -> 157.2737 | O21: =Acciones!$D$751*EXP((J$2-J$3/2)*(1)+J$4*_xlfn.NORM.S.INV(RAND())*SQRT(1)) -> 1006.8628 | P21: =Acciones!$E$751*EXP((K$2-K$3/2)*(1)+K$4*_xlfn.NORM.S.INV(RAND())*SQRT(1)) -> 0.12238035 | R21: =M21/Acciones!$B$751*$I$10 + N21/Acciones!$C$751*$I$11 + O21/Acciones!$D$751*$I$12 + P21/Acciones!$D$751*$I$13 -> 23303.951 | T21: =R21-$I$14 -> -5196.0489 | V21: -6731.8805
A22: =Acciones!A22 -> 45029 | B22: =LN(Acciones!B22/Acciones!B21) -> 0.015015941 | C22: =LN(Acciones!C22/Acciones!C21) -> 0.15584199 | D22: =LN(Acciones!D22/Acciones!D21) -> 0.0048382721 | E22: =LN(Acciones!E22/Acciones!E21) -> -0.01792626 | M22: =Acciones!$B$751*EXP((H$2-H$3/2)*(1)+H$4*_xlfn.NORM.S.INV(RAND())*SQRT(1)) -> 11.023641 | N22: =Acciones!$C$751*EXP((I$2-I$3/2)*(1)+I$4*_xlfn.NORM.S.INV(RAND())*SQRT(1)) -> 155.25745 | O22: =Acciones!$D$751*EXP((J$2-J$3/2)*(1)+J$4*_xlfn.NORM.S.INV(RAND())*SQRT(1)) -> 986.87532 | P22: =Acciones!$E$751*EXP((K$2-K$3/2)*(1)+K$4*_xlfn.NORM.S.INV(RAND())*SQRT(1)) -> 0.13808512 | R22: =M22/Acciones!$B$751*$I$10 + N22/Acciones!$C$751*$I$11 + O22/Acciones!$D$751*$I$12 + P22/Acciones!$D$751*$I$13 -> 23116.206 | T22: =R22-$I$14 -> -5383.7935 | V22: -6716.404
A23: =Acciones!A23 -> 45030 | B23: =LN(Acciones!B23/Acciones!B22) -> 0.012283341 | C23: =LN(Acciones!C23/Acciones!C22) -> 0.025524369 | D23: =LN(Acciones!D23/Acciones!D22) -> -0.01367453 | E23: =LN(Acciones!E23/Acciones!E22) -> -0.031498637 | M23: =Acciones!$B$751*EXP((H$2-H$3/2)*(1)+H$4*_xlfn.NORM.S.INV(RAND())*SQRT(1)) -> 10.502229 | N23: =Acciones!$C$751*EXP((I$2-I$3/2)*(1)+I$4*_xlfn.NORM.S.INV(RAND())*SQRT(1)) -> 157.11587 | O23: =Acciones!$D$751*EXP((J$2-J$3/2)*(1)+J$4*_xlfn.NORM.S.INV(RAND())*SQRT(1)) -> 1002.9778 | P23: =Acciones!$E$751*EXP((K$2-K$3/2)*(1)+K$4*_xlfn.NORM.S.INV(RAND())*SQRT(1)) -> 0.13361631 | R23: =M23/Acciones!$B$751*$I$10 + N23/Acciones!$C$751*$I$11 + O23/Acciones!$D$751*$I$12 + P23/Acciones!$D$751*$I$13 -> 23226.236 | T23: =R23-$I$14 -> -5273.764 | V23: -6713.8969
A24: =Acciones!A24 -> 45033 | B24: =LN(Acciones!B24/Acciones!B23) -> -0.019213972 | C24: =LN(Acciones!C24/Acciones!C23) -> -0.030776057 | D24: =LN(Acciones!D24/Acciones!D23) -> 0 | E24: =LN(Acciones!E24/Acciones!E23) -> -0.016129366 | M24: =Acciones!$B$751*EXP((H$2-H$3/2)*(1)+H$4*_xlfn.NORM.S.INV(RAND())*SQRT(1)) -> 10.48777 | N24: =Acciones!$C$751*EXP((I$2-I$3/2)*(1)+I$4*_xlfn.NORM.S.INV(RAND())*SQRT(1)) -> 152.51505 | O24: =Acciones!$D$751*EXP((J$2-J$3/2)*(1)+J$4*_xlfn.NORM.S.INV(RAND())*SQRT(1)) -> 994.28163 | P24: =Acciones!$E$751*EXP((K$2-K$3/2)*(1)+K$4*_xlfn.NORM.S.INV(RAND())*SQRT(1)) -> 0.13290068 | R24: =M24/Acciones!$B$751*$I$10 + N24/Acciones!$C$751*$I$11 + O24/Acciones!$D$751*$I$12 + P24/Acciones!$D$751*$I$13 -> 22847.221 | T24: =R24-$I$14 -> -5652.7787 | V24: -6710.4163
A25: =Acciones!A25 -> 45034 | B25: =LN(Acciones!B25/Acciones!B24) -> -0.021084611 | C25: =LN(Acciones!C25/Acciones!C24) -> 0.018569593 | D25: =LN(Acciones!D25/Acciones!D24) -> 0.013656922 | E25: =LN(Acciones!E25/Acciones!E24) -> -0.0027137032 | M25: =Acciones!$B$751*EXP((H$2-H$3/2)*(1)+H$4*_xlfn.NORM.S.INV(RAND())*SQRT(1)) -> 10.763503 | N25: =Acciones!$C$751*EXP((I$2-I$3/2)*(1)+I$4*_xlfn.NORM.S.INV(RAND())*SQRT(1)) -> 142.1849 | O25: =Acciones!$D$751*EXP((J$2-J$3/2)*(1)+J$4*_xlfn.NORM.S.INV(RAND())*SQRT(1)) -> 1006.2069 | P25: =Acciones!$E$751*EXP((K$2-K$3/2)*(1)+K$4*_xlfn.NORM.S.INV(RAND())*SQRT(1)) -> 0.12880407 | R25: =M25/Acciones!$B$751*$I$10 + N25/Acciones!$C$751*$I$11 + O25/Acciones!$D$751*$I$12 + P25/Acciones!$D$751*$I$13 -> 22410.106 | T25: =R25-$I$14 -> -6089.8939 | V25: -6709.0396
A26: =Acciones!A26 -> 45035 | B26: =LN(Acciones!B26/Acciones!B25) -> -0.023067746 | C26: =LN(Acciones!C26/Acciones!C25) -> -0.088801925 | D26: =LN(Acciones!D26/Acciones!D25) -> -0.0046887321 | E26: =LN(Acciones!E26/Acciones!E25) -> -0.016438776 | M26: =Acciones!$B$751*EXP((H$2-H$3/2)*(1)+H$4*_xlfn.NORM.S.INV(RAND())*SQRT(1)) -> 10.91569 | N26: =Acciones!$C$751*EXP((I$2-I$3/2)*(1)+I$4*_xlfn.NORM.S.INV(RAND())*SQRT(1)) -> 158.76942 | O26: =Acciones!$D$751*EXP((J$2-J$3/2)*(1)+J$4*_xlfn.NORM.S.INV(RAND())*SQRT(1)) -> 984.29041 | P26: =Acciones!$E$751*EXP((K$2-K$3/2)*(1)+K$4*_xlfn.NORM.S.INV(RAND())*SQRT(1)) -> 0.12978328 | R26: =M26/Acciones!$B$751*$I$10 + N26/Acciones!$C$751*$I$11 + O26/Acciones!$D$751*$I$12 + P26/Acciones!$D$751*$I$13 -> 23274.92 | T26: =R26-$I$14 -> -5225.0801 | V26: -6706.4781
... A751: =Acciones!A751 -> 46090 | B751: =LN(Acciones!B751/Acciones!B750) -> -0.003659653 | C751: =LN(Acciones!C751/Acciones!C750) -> 0.069603331 | D751: =LN(Acciones!D751/Acciones!D750) -> -0.016973237 | E751: =LN(Acciones!E751/Acciones!E750) -> -0.052446472 | M751: =Acciones!$B$751*EXP((H$2-H$3/2)*(1)+H$4*_xlfn.NORM.S.INV(RAND())*SQRT(1)) -> 10.535707 | N751: =Acciones!$C$751*EXP((I$2-I$3/2)*(1)+I$4*_xlfn.NORM.S.INV(RAND())*SQRT(1)) -> 155.82709 | O751: =Acciones!$D$751*EXP((J$2-J$3/2)*(1)+J$4*_xlfn.NORM.S.INV(RAND())*SQRT(1)) -> 1004.5546 | P751: =Acciones!$E$751*EXP((K$2-K$3/2)*(1)+K$4*_xlfn.NORM.S.INV(RAND())*SQRT(1)) -> 0.12981751 | R751: =M751/Acciones!$B$751*$I$10 + N751/Acciones!$C$751*$I$11 + O751/Acciones!$D$751*$I$12 + P751/Acciones!$D$751*$I$13 -> 23172.279 | T751: =R751-$I$14 -> -5327.7207 | V751: -3913.9524
M752: =Acciones!$B$751*EXP((H$2-H$3/2)*(1)+H$4*_xlfn.NORM.S.INV(RAND())*SQRT(1)) -> 11.012329 | N752: =Acciones!$C$751*EXP((I$2-I$3/2)*(1)+I$4*_xlfn.NORM.S.INV(RAND())*SQRT(1)) -> 139.16602 | O752: =Acciones!$D$751*EXP((J$2-J$3/2)*(1)+J$4*_xlfn.NORM.S.INV(RAND())*SQRT(1)) -> 1032.2343 | P752: =Acciones!$E$751*EXP((K$2-K$3/2)*(1)+K$4*_xlfn.NORM.S.INV(RAND())*SQRT(1)) -> 0.12593894 | R752: =M752/Acciones!$B$751*$I$10 + N752/Acciones!$C$751*$I$11 + O752/Acciones!$D$751*$I$12 + P752/Acciones!$D$751*$I$13 -> 22562.123 | T752: =R752-$I$14 -> -5937.8772 | V752: -3799.2899
M753: =Acciones!$B$751*EXP((H$2-H$3/2)*(1)+H$4*_xlfn.NORM.S.INV(RAND())*SQRT(1)) -> 10.98732 | N753: =Acciones!$C$751*EXP((I$2-I$3/2)*(1)+I$4*_xlfn.NORM.S.INV(RAND())*SQRT(1)) -> 138.3868 | O753: =Acciones!$D$751*EXP((J$2-J$3/2)*(1)+J$4*_xlfn.NORM.S.INV(RAND())*SQRT(1)) -> 1000.4362 | P753: =Acciones!$E$751*EXP((K$2-K$3/2)*(1)+K$4*_xlfn.NORM.S.INV(RAND())*SQRT(1)) -> 0.12193578 | R753: =M753/Acciones!$B$751*$I$10 + N753/Acciones!$C$751*$I$11 + O753/Acciones!$D$751*$I$12 + P753/Acciones!$D$751*$I$13 -> 22186.922 | T753: =R753-$I$14 -> -6313.0782 | V753: -3722.1993

Sheet VAR PARAMETRICO
A1: =Acciones!A1 -> Fecha | B1: AGUAR | C1: MARAR | D1: NKER | E1: TEAKCPOR
A2: =Acciones!A3 -> 44999 | B2: =Acciones!B3/Acciones!B2 -1 -> 0.016117776 | C2: =Acciones!C3/Acciones!C2 -1 -> 0.039212565 | D2: =Acciones!D3/Acciones!D2 -1 -> -0.012162664 | E2: =Acciones!E3/Acciones!E2 -1 -> 0 | H2: AGUAR | I2: MARAR | J2: NKER | K2: TEAKCPOR | M2: a
A3: =Acciones!A4 -> 45000 | B3: =Acciones!B4/Acciones!B3 -1 -> -0.035862108 | C3: =Acciones!C4/Acciones!C3 -1 -> 0.0077284763 | D3: =Acciones!D4/Acciones!D3 -1 -> 0.023894168 | E3: =Acciones!E4/Acciones!E3 -1 -> -0.053846162 | G3: AGUAR | H3: =VARP('VAR PARAMETRICO'!$B$2:$B$750) -> 0.00051160714 | I3: =H4 -> 4.8919819e-05 | J3: =H5 -> -2.7018384e-05 | K3: =H6 -> -2.324366e-05 | M3: 3500
A4: =Acciones!A5 -> 45001 | B4: =Acciones!B5/Acciones!B4 -1 -> -0.0039341194 | C4: =Acciones!C5/Acciones!C4 -1 -> 0.080451105 | D4: =Acciones!D5/Acciones!D4 -1 -> 0.005611838 | E4: =Acciones!E5/Acciones!E4 -1 -> 0.056910579 | G4: MARAR | H4: 4.8919819e-05 | I4: =VARP('VAR PARAMETRICO'!$C$2:$C$750) -> 0.0037391323 | J4: =I5 -> 0.00016501746 | K4: =I6 -> 0.00025162577 | M4: 9500
A5: =Acciones!A6 -> 45002 | B5: =Acciones!B6/Acciones!B5 -1 -> -0.0053860791 | C5: =Acciones!C6/Acciones!C5 -1 -> 0.07863607 | D5: =Acciones!D6/Acciones!D5 -1 -> -0.00011095101 | E5: =Acciones!E6/Acciones!E5 -1 -> 0 | G5: NKER | H5: -2.7018384e-05 | I5: 0.00016501746 | J5: =VARP('VAR PARAMETRICO'!$D$2:$D$750) -> 0.00052633803 | K5: =J6 -> 6.3489237e-05 | M5: 10000
A6: =Acciones!A7 -> 45006 | B6: =Acciones!B7/Acciones!B6 -1 -> -0.02382665 | C6: =Acciones!C7/Acciones!C6 -1 -> 0.06490321 | D6: =Acciones!D7/Acciones!D6 -1 -> 0.036580798 | E6: =Acciones!E7/Acciones!E6 -1 -> -0.038461562 | G6: TEAKCPOR | H6: -2.324366e-05 | I6: 0.00025162577 | J6: 6.3489237e-05 | K6: =VARP('VAR PARAMETRICO'!$E$2:$E$750) -> 0.0045840602 | M6: 5500
A7: =Acciones!A8 -> 45007 | B7: =Acciones!B8/Acciones!B7 -1 -> 0.013313524 | C7: =Acciones!C8/Acciones!C7 -1 -> -0.12401552 | D7: =Acciones!D8/Acciones!D7 -1 -> -0.047147123 | E7: =Acciones!E8/Acciones!E7 -1 -> -0.013333321
A8: =Acciones!A9 -> 45008 | B8: =Acciones!B9/Acciones!B8 -1 -> -0.030656941 | C8: =Acciones!C9/Acciones!C8 -1 -> 0.090808529 | D8: =Acciones!D9/Acciones!D8 -1 -> 0.0044843212 | E8: =Acciones!E9/Acciones!E8 -1 -> -0.027027065 | G8: aT = | H8: 3500 | I8: 9500 | J8: 10000 | K8: 5500 | M8: =SUM(H8:K8) -> 28500
A9: =Acciones!A10 -> 45009 | B9: =Acciones!B10/Acciones!B9 -1 -> 0.017319327 | C9: =Acciones!C10/Acciones!C9 -1 -> -0.0836926 | D9: =Acciones!D10/Acciones!D9 -1 -> -0.0073656498 | E9: =Acciones!E10/Acciones!E9 -1 -> 0.027777818
A10: =Acciones!A11 -> 45012 | B10: =Acciones!B11/Acciones!B10 -1 -> 0.009622589 | C10: =Acciones!C11/Acciones!C10 -1 -> -0.082618337 | D10: =Acciones!D11/Acciones!D10 -1 -> -0.025185995 | E10: =Acciones!E11/Acciones!E10 -1 -> 0
A11: =Acciones!A12 -> 45013 | B11: =Acciones!B12/Acciones!B11 -1 -> 0.018328348 | C11: =Acciones!C12/Acciones!C11 -1 -> 0.0012822309 | D11: =Acciones!D12/Acciones!D11 -1 -> -0.012207571 | E11: =Acciones!E12/Acciones!E11 -1 -> 0 | G11: s2P = | H11: {=MMULT(MMULT(H8:K8,H3:K6),M3:M6)} -> 600124.53 | J11: f(z*) = | K11: =_xlfn.NORM.S.DIST(H17,FALSE) -> 0.05844507
A12: =Acciones!A13 -> 45014 | B12: =Acciones!B13/Acciones!B12 -1 -> -0.021958151 | C12: =Acciones!C13/Acciones!C12 -1 -> 0.087080961 | D12: =Acciones!D13/Acciones!D12 -1 -> 0.013059251 | E12: =Acciones!E13/Acciones!E12 -1 -> -0.0054054002 | J12: F(z*) = | K12: =_xlfn.NORM.S.DIST(-H17,TRUE) -> 0.975
A13: =Acciones!A14 -> 45015 | B13: =Acciones!B14/Acciones!B13 -1 -> 0.015826263 | C13: =Acciones!C14/Acciones!C13 -1 -> -0.033331007 | D13: =Acciones!D14/Acciones!D13 -1 -> 0 | E13: =Acciones!E14/Acciones!E13 -1 -> -0.043478283 | G13: sP = | H13: =SQRT(H11) -> 774.67705
A14: =Acciones!A15 -> 45016 | B14: =Acciones!B15/Acciones!B14 -1 -> 0.0018115471 | C14: =Acciones!C15/Acciones!C14 -1 -> 0.11949819 | D14: =Acciones!D15/Acciones!D14 -1 -> 0.018902514 | E14: =Acciones!E15/Acciones!E14 -1 -> 0.07670454 | J14: CVaR1 día = | K14: =H13*(K11/K12) -> 46.436979
A15: =Acciones!A16 -> 45019 | B15: =Acciones!B16/Acciones!B15 -1 -> -0.046292883 | C15: =Acciones!C16/Acciones!C15 -1 -> -0.015175739 | D15: =Acciones!D16/Acciones!D15 -1 -> -0.0061672503 | E15: =Acciones!E16/Acciones!E15 -1 -> 0.029023782 | G15: a = | H15: 0.975 | K15: =K14+H19 -> 1564.7761 | L15: =K15/M8 -> 0.054904424
A16: =Acciones!A17 -> 45020 | B16: =Acciones!B17/Acciones!B16 -1 -> 0.014410191 | C16: =Acciones!C17/Acciones!C16 -1 -> 0.0022756231 | D16: =Acciones!D17/Acciones!D16 -1 -> 0.01986447 | E16: =Acciones!E17/Acciones!E16 -1 -> 0.0102564
A17: =Acciones!A18 -> 45021 | B17: =Acciones!B18/Acciones!B17 -1 -> -0.00971956 | C17: =Acciones!C18/Acciones!C17 -1 -> -0.062082338 | D17: =Acciones!D18/Acciones!D17 -1 -> 0 | E17: =Acciones!E18/Acciones!E17 -1 -> 0.012690343 | G17: Z1-a = | H17: =_xlfn.NORM.S.INV(1-H15) -> -1.959964 | J17: Capital = | K17: =H22*3 -> 14404.23
A18: =Acciones!A19 -> 45026 | B18: =Acciones!B19/Acciones!B18 -1 -> 0.01321258 | C18: =Acciones!C19/Acciones!C18 -1 -> 0.13231432 | D18: =Acciones!D19/Acciones!D18 -1 -> 0.049098136 | E18: =Acciones!E19/Acciones!E18 -1 -> -0.010025053 | K18: =K17/M8 -> 0.50541156
A19: =Acciones!A20 -> 45027 | B19: =Acciones!B20/Acciones!B19 -1 -> 0.042473863 | C19: =Acciones!C20/Acciones!C19 -1 -> 0.14269134 | D19: =Acciones!D20/Acciones!D19 -1 -> -0.047481037 | E19: =Acciones!E20/Acciones!E19 -1 -> -0.0025316431 | G19: VaR1 día = | H19: =H13*ABS(H17) -> 1518.3391
A20: =Acciones!A21 -> 45028 | B20: =Acciones!B21/Acciones!B20 -1 -> -0.031451048 | C20: =Acciones!C21/Acciones!C20 -1 -> -0.048110331 | D20: =Acciones!D21/Acciones!D20 -1 -> 0.014117337 | E20: =Acciones!E21/Acciones!E20 -1 -> 0 | H20: =H19/M8 -> 0.053275057
A21: =Acciones!A22 -> 45029 | B21: =Acciones!B22/Acciones!B21 -1 -> 0.015129247 | C21: =Acciones!C22/Acciones!C21 -1 -> 0.16864153 | D21: =Acciones!D22/Acciones!D21 -1 -> 0.0048499955 | E21: =Acciones!E22/Acciones!E21 -1 -> -0.017766541
A22: =Acciones!A23 -> 45030 | B22: =Acciones!B23/Acciones!B22 -1 -> 0.012359091 | C22: =Acciones!C23/Acciones!C22 -1 -> 0.025852905 | D22: =Acciones!D23/Acciones!D22 -1 -> -0.013581458 | E22: =Acciones!E23/Acciones!E22 -1 -> -0.031007723 | G22: VaR10 días = | H22: =H19*SQRT(10) -> 4801.4099
A23: =Acciones!A24 -> 45033 | B23: =Acciones!B24/Acciones!B23 -1 -> -0.019030561 | C23: =Acciones!C24/Acciones!C23 -1 -> -0.030307295 | D23: =Acciones!D24/Acciones!D23 -1 -> 0 | E23: =Acciones!E24/Acciones!E23 -1 -> -0.015999985 | H23: =H22/M8 -> 0.16847052
A24: =Acciones!A25 -> 45034 | B24: =Acciones!B25/Acciones!B24 -1 -> -0.020863885 | C24: =Acciones!C25/Acciones!C24 -1 -> 0.01874308 | D24: =Acciones!D25/Acciones!D24 -1 -> 0.013750604 | E24: =Acciones!E25/Acciones!E24 -1 -> -0.0027100245
A25: =Acciones!A26 -> 45035 | B25: =Acciones!B26/Acciones!B25 -1 -> -0.02280372 | C25: =Acciones!C26/Acciones!C25 -1 -> -0.0849732 | D25: =Acciones!D26/Acciones!D25 -1 -> -0.0046777572 | E25: =Acciones!E26/Acciones!E25 -1 -> -0.016304397
A26: =Acciones!A27 -> 45036 | B26: =Acciones!B27/Acciones!B26 -1 -> 0.00076515436 | C26: =Acciones!C27/Acciones!C26 -1 -> -0.10809971 | D26: =Acciones!D27/Acciones!D26 -1 -> -0.0089413635 | E26: =Acciones!E27/Acciones!E26 -1 -> -0.0055248568
A27: =Acciones!A28 -> 45037 | B27: =Acciones!B28/Acciones!B27 -1 -> 0.026758427 | C27: =Acciones!C28/Acciones!C27 -1 -> -0.066294833 | D27: =Acciones!D28/Acciones!D27 -1 -> 0.0022221209 | E27: =Acciones!E28/Acciones!E27 -1 -> -0.013888876
A28: =Acciones!A29 -> 45040 | B28: =Acciones!B29/Acciones!B28 -1 -> 0.0033506666 | C28: =Acciones!C29/Acciones!C28 -1 -> 0.0031113877 | D28: =Acciones!D29/Acciones!D28 -1 -> 0.010199353 | E28: =Acciones!E29/Acciones!E28 -1 -> -0.014084494
A29: =Acciones!A30 -> 45041 | B29: =Acciones!B30/Acciones!B29 -1 -> -0.018181853 | C29: =Acciones!C30/Acciones!C29 -1 -> 0.011166272 | D29: =Acciones!D30/Acciones!D29 -1 -> -0.014481801 | E29: =Acciones!E30/Acciones!E29 -1 -> -0.011428561
A30: =Acciones!A31 -> 45042 | B30: =Acciones!B31/Acciones!B30 -1 -> -0.026077016 | C30: =Acciones!C31/Acciones!C30 -1 -> 0.055889574 | D30: =Acciones!D31/Acciones!D30 -1 -> -0.004458702 | E30: =Acciones!E31/Acciones!E30 -1 -> 0
A31: =Acciones!A32 -> 45043 | B31: =Acciones!B32/Acciones!B31 -1 -> -0.012417522 | C31: =Acciones!C32/Acciones!C31 -1 -> 0.047527701 | D31: =Acciones!D32/Acciones!D31 -1 -> 0.012527766 | E31: =Acciones!E32/Acciones!E31 -1 -> 0
A32: =Acciones!A33 -> 45044 | B32: =Acciones!B33/Acciones!B32 -1 -> -0.013752504 | C32: =Acciones!C33/Acciones!C32 -1 -> 0.0067114469 | D32: =Acciones!D33/Acciones!D32 -1 -> 0.0044189288 | E32: =Acciones!E33/Acciones!E32 -1 -> -0.011560682
A33: =Acciones!A34 -> 45048 | B33: =Acciones!B34/Acciones!B33 -1 -> -0.017928316 | C33: =Acciones!C34/Acciones!C33 -1 -> -0.054325072 | D33: =Acciones!D34/Acciones!D33 -1 -> 0.0065993394 | E33: =Acciones!E34/Acciones!E33 -1 -> 0
A34: =Acciones!A35 -> 45049 | B34: =Acciones!B35/Acciones!B34 -1 -> 0.041785014 | C34: =Acciones!C35/Acciones!C34 -1 -> -0.018061094 | D34: =Acciones!D35/Acciones!D34 -1 -> -0.01223789 | E34: =Acciones!E35/Acciones!E34 -1 -> 0.052631528
A35: =Acciones!A36 -> 45050 | B35: =Acciones!B36/Acciones!B35 -1 -> -0.045950107 | C35: =Acciones!C36/Acciones!C35 -1 -> 0.09172901 | D35: =Acciones!D36/Acciones!D35 -1 -> -0.020619495 | E35: =Acciones!E36/Acciones!E35 -1 -> -0.016666651
... A750: =Acciones!A751 -> 46090 | B750: =Acciones!B751/Acciones!B750 -1 -> -0.0036529646 | C750: =Acciones!C751/Acciones!C750 -1 -> 0.072082834 | D750: =Acciones!D751/Acciones!D750 -1 -> -0.016830003 | E750: =Acciones!E751/Acciones!E750 -1 -> -0.051094887

Sheet Resumen VaR
B2: Confianza = | C2: ='VAR PARAMETRICO'!H15 -> 0.975
B3: Cuantil = | C3: ='VAR HIST'!E3 -> 18.75
B4: P = | C4: ='VAR PARAMETRICO'!M8 -> 28500
B7: Valor en Riesgo
B8: Concepto | C8: Simulación Histórica MXN $ | D8: Simulación Histórica %P | E8: Monte Carlo MXN $ | F8: Monte Carlo %P | G8: Paramétrico MXN $ | H8: Paramétrico %P
B9: VaR97.5%, 1 día = | C9: ='VAR HIST'!E4 -> 1380.0026 | D9: ='VAR HIST'!E5 -> 0.048421145 | E9: ='VAR SM'!Y7 -> 6710.4163 | F9: ='VAR SM'!Z7 -> 0.2354532 | G9: ='VAR PARAMETRICO'!H19 -> 1518.3391 | H9: ='VAR PARAMETRICO'!H20 -> 0.053275057
B10: CVaR97.5%, 1 día = | C10: ='VAR HIST'!E6 -> 1670.9708 | D10: ='VAR HIST'!E7 -> 0.058630556 | E10: ='VAR SM'!Y8 -> 6864.8264 | F10: ='VAR SM'!Z8 -> 0.2408711 | G10: ='VAR PARAMETRICO'!K15 -> 1564.7761 | H10: ='VAR PARAMETRICO'!L15 -> 0.054904424
B12: VaR97.5%, 10 días = | C12: ='VAR HIST'!E9 -> 4363.9515 | D12: ='VAR HIST'!E10 -> 0.1531211 | E12: ='VAR SM'!Y10 -> 21220.2 | F12: ='VAR SM'!Z10 -> 0.74456841 | G12: ='VAR PARAMETRICO'!H22 -> 4801.4099 | H12: ='VAR PARAMETRICO'!H23 -> 0.16847052
B13: CapitalRiesgo de mercado = | C13: ='VAR HIST'!E13 -> 13091.854 | D13: ='VAR HIST'!E14 -> 0.45936331 | E13: ='VAR SM'!Y11 -> 63660.599 | F13: ='VAR SM'!Z11 -> 2.2337052 | G13: ='VAR PARAMETRICO'!K17 -> 14404.23 | H13: ='VAR PARAMETRICO'!K18 -> 0.50541156
